Workbook

Sheet 高科对内
A1: 销售员 | B1: 付款方式 | C1: 运费 | D1: 单位名称 | E1: 合同号 | F1: 合同有效期 | G1: 产品规格 | H1: 合同量 | I1: 销售单价 | J1: 销售金额 | K1: 实际出库 | L1: 未发量 | M1: 到款金额 | N1: 余款 | O1: 应收款 | P1: 出厂价 | Q1: 指导价 | R1: 合同总金额￥ | S1: 包装 | T1: 托盘 | U1: 缠绕膜 | V1: 扎带 | W1: 卡扣 | X1: 吨袋 | Y1: 绑带
A2: 毛晓翔 | B2: 本周35%预付，下周付款45%，本月底之前付清全款。 | C2: 自提 | D2: 浙江五合进出口有限公司 | E2: CHDN-20260312-106 | F2: 46174 | G2: CH301 | H2: 806.4 | I2: 15600 | J2: =H2*I2 -> 12579840 | K2: =680.96+125.44 -> 806.4 | L2: =H2-K2 -> 0 | M2: =高科收款!D6+高科收款!D10+高科收款!D17 -> 12579840 | N2: =J2-M2 -> 0 | O2: =K2*I2-M2 -> 0 | P2: 15305 | R2: =P2*H2 -> 12341952 | S2: 560kg/包，吨袋包装。 | T2: 720 | V2: 23 | W2: 2880 | X2: 1440
A3: 毛晓翔 | B3: 款到发货 | C3: 自提 | D3: 上海穗广贸易有限公司 | E3: CHDN-20260313-111 | F3: 46125 | G3: CH520 | H3: 18 | I3: 16100 | J3: =H3*I3 -> 289800 | K3: 18 | L3: =H3-K3 -> 0 | M3: =高科收款!D9 -> 289800 | N3: =J3-M3 -> 0 | O3: =K3*I3-M3 -> 0 | P3: 16100 | Q3: 16100 | R3: =P3*H3 -> 289800 | S3: 15kg/包散装，1*40HQ.
A4: 张晓敏 | B4: 100%预付 | C4: 送到 | D4: 浙江五合进出口有限公司 | E4: CHDN-20260319-133 | F4: 46131 | G4: CH332 | H4: 10 | I4: 16000 | J4: =H4*I4 -> 160000 | K4: =高科出库!E28 -> 10 | L4: =H4-K4 -> 0 | M4: =高科收款!D11 -> 160000 | N4: =J4-M4 -> 0 | O4: =K4*I4-M4 -> 0 | P4: 15860 | Q4: 15600 | R4: =P4*H4 -> 158600 | S4: 小包散装
A5: 毛晓翔 | B5: 款到发货 | C5: 自提 | D5: 苏州名创新材料有限公司 | E5: CHDN-20260323-160 | F5: 46111 | G5: CH510 | H5: 6 | I5: 17300 | J5: =H5*I5 -> 103800 | K5: 6 | L5: =H5-K5 -> 0 | M5: 103800 | N5: =J5-M5 -> 0 | O5: =K5*I5-M5 -> 0 | P5: 17300 | Q5: 17250 | R5: =P5*H5 -> 103800 | S5: 15kg/包散装
A6: 毛晓翔 | B6: 款到发货 | C6: 自提 | D6: 苏州名创新材料有限公司 | E6: CHDN-20260323-160 | F6: 46111 | G6: CH506 | H6: 6 | I6: 17500 | J6: =H6*I6 -> 105000 | K6: 6 | L6: =H6-K6 -> 0 | M6: 105000 | N6: =J6-M6 -> 0 | O6: =K6*I6-M6 -> 0 | P6: 17500 | Q6: 17250 | R6: =P6*H6 -> 105000 | S6: 15kg/包散装
A7: 毛晓翔 | B7: 100%预付 | C7: 送到 | D7: 昆山九子莲汽车隔音材料有限公司 | E7: CHDN-20260324-177 | F7: 46111 | G7: CH520 | H7: 11.04 | I7: 18100 | J7: =H7*I7 -> 199824 | K7: 11.04 | L7: =H7-K7 -> 0 | M7: =高科收款!D13 -> 199824 | N7: =J7-M7 -> 0 | O7: =K7*I7-M7 -> 0 | P7: 17945 | Q7: 17100 | R7: =P7*H7 -> 198112.8 | S7: 15kg/包散装
A8: 毛晓翔 | B8: 20%定金2026年4月10日之前付款，分批发货到7月底，发货前对应数量付全款，定金最后一批发货抵扣。 | C8: 自提 | D8: 浙江五合进出口有限公司 | E8: CHDN-20260325-180 | F8: 46249 | G8: CH332 | H8: 1708.8 | I8: 16489 | J8: =H8*I8 -> 28176403 | K8: =1401.6+153.6+153.6 -> 1708.8 | L8: =H8-K8 -> 0 | M8: =高科收款!D20+高科收款!D34+高科收款!D35+高科收款!D51+高科收款!D64+高科收款!D74+高科收款!D77+高科收款!D113+高科收款!D114+高科收款!D126 -> 28176403 | N8: =J8-M8 -> 0 | O8: =K8*I8-M8 -> 0 | P8: 16000 | Q8: 16000 | R8: =P8*H8 -> 27340800 | S8: 600kg/包，吨袋包装，其中一半带托盘，19.2吨/柜 | T8: =1248+176 -> 1424 | V8: =39+5.5 -> 44.5 | W8: =4992+704 -> 5696 | X8: =2496+352 -> 2848
A9: 张晓敏 | B9: 100%预付 | C9: 送到 | D9: 浙江五合进出口有限公司 | E9: CHDN-20260401-201 | F9: 46143 | G9: CH332 | H9: 43.28 | I9: 18200 | J9: =H9*I9 -> 787696 | K9: 43.28 | L9: =H9-K9 -> 0 | M9: =873600-(48-H9)*I9 -> 787696 | N9: =J9-M9 -> 0 | O9: =K9*I9-M9 -> 0 | P9: 17735 | Q9: 17600 | R9: =P9*H9 -> 767570.8 | S9: 240kg/包，吨袋包装 | X9: 200(小尺寸）
A10: 毛晓翔 | B10: 20%定金，提货前全款。 | C10: 自提 | D10: 宁波方觉科技有限公司 | E10: CHDN-20260408-214 | F10: 46142 | G10: CH520 | H10: 187.5 | I10: 21000 | J10: =H10*I10 -> 3937500 | K10: 187.5 | L10: =H10-K10 -> 0 | M10: =高科收款!D19+高科收款!D22+高科收款!D29 -> 3937500 | N10: =J10-M10 -> 0 | O10: =K10*I10-M10 -> 0 | P10: 21000 | Q10: 20500 | R10: =P10*H10 -> 3937500 | S10: 15kg/包散装
A11: 张晓敏 | B11: 100%预付 | C11: 自提 | D11: 浙江五合进出口有限公司 | E11: CHDN-20260511-234 | F11: 46184 | G11: CH301 | H11: 38 | I11: 14800 | J11: =H11*I11 -> 562400 | K11: 38 | L11: =H11-K11 -> 0 | M11: 562400 | N11: =J11-M11 -> 0 | O11: =K11*I11-M11 -> 0 | P11: 14800 | R11: =P11*H11 -> 562400 | S11: 20kg/包散装
A12: 张晓敏 | B12: 100%预付 | C12: 自提 | D12: 宁波澜塑新材料有限公司 | E12: CHDN-20260513-237 | F12: 46172 | G12: CH301 | H12: 4 | I12: 14600 | J12: =H12*I12 -> 58400 | K12: 4 | L12: =H12-K12 -> 0 | M12: 58400 | N12: =J12-M12 -> 0 | O12: =K12*I12-M12 -> 0 | P12: 14600 | R12: =P12*H12 -> 58400 | S12: 小包散货包装
A13: 张晓敏 | B13: 100%预付 | C13: 自提 | D13: 宁波澜塑新材料有限公司 | E13: CHDN-20260513-237 | F13: 46172 | G13: CH608 | H13: 2.5 | I13: 16600 | J13: =H13*I13 -> 41500 | K13: 2.5 | L13: =H13-K13 -> 0 | M13: 41500 | N13: =J13-M13 -> 0 | O13: =K13*I13-M13 -> 0 | P13: 16600 | R13: =P13*H13 -> 41500 | S13: 小包散货包装
A14: 毛晓翔 | B14: 全款承兑支付。 | C14: 自提 | D14: 金华穗广 | E14: CHDN-20260517-243 | F14: 46203 | G14: CH332 | H14: 100 | I14: 15850 | J14: =H14*I14 -> 1585000 | K14: =53.76+41.36+4.88 -> 100 | L14: =H14-K14 -> 0 | M14: =高科收款!D38 -> 1585000 | N14: =J14-M14 -> 0 | O14: =K14*I14-M14 -> 0 | P14: 15635 | Q14: 15500 | R14: =P14*H14 -> 1563500 | S14: 20kg小包带托盘 | T14: 320 | U14: 25 | V14: 10 | W14: 1280
A15: 张晓敏 | B15: 100%全款预付 | C15: 送到 | D15: 浙江五合进出口有限公司 | E15: CHDN-20260601-273 | F15: 46204 | G15: CH332 | H15: 24.2 | I15: 15200 | J15: =H15*I15 -> 367840 | K15: 24.2 | L15: =H15-K15 -> 0 | M15: =高科收款!D31+高科收款!D45-6688 -> 367840 | N15: =J15-M15 -> 0 | O15: =K15*I15-M15 -> 0 | P15: 14725 | Q15: 14500 | R15: =P15*H15 -> 356345 | S15: 220kg/包，吨袋包装 | X15: 112
A16: 毛晓翔 | B16: 全款承兑支付 | C16: 自提 | D16: 金华穗广 | E16: CHDN-20260601-274 | F16: 46234 | G16: CH332 | H16: 100 | I16: 14820 | J16: =H16*I16 -> 1482000 | K16: 100 | L16: =H16-K16 -> 0 | M16: =高科收款!D47 -> 1482000 | N16: =J16-M16 -> 0 | O16: =K16*I16-M16 -> 0 | P16: 14605 | Q16: 14500 | R16: =P16*H16 -> 1460500 | S16: 20kg小包带托盘 | T16: 320 | U16: 25 | V16: 10 | W16: 1280
A17: 毛晓翔 | B17: 款到发货 | C17: 自提 | D17: 苏州名创新材料有限公司 | E17: CHDN-20260610-293 | F17: 46188 | G17: CH506 | H17: 5.01 | I17: 16300 | J17: =H17*I17 -> 81663 | K17: =5.01 -> 5.01 | L17: =H17-K17 -> 0 | M17: 81663 | N17: =J17-M17 -> 0 | O17: =K17*I17-M17 -> 0 | P17: 16300 | Q17: 16250 | R17: =P17*H17 -> 81663 | S17: 15kg/包散装
A18: 毛晓翔 | B18: 全款预付 | C18: 自提 | D18: 宁海赤欣电器有限公司 | E18: CHDN-20260612-301 | F18: 46215 | G18: CH301 | H18: 17.92 | I18: 13400 | J18: =H18*I18 -> 240128 | K18: 17.92 | L18: =H18-K18 -> 0 | M18: =高科收款!D61 -> 240128 | N18: =J18-M18 -> 0 | O18: =K18*I18-M18 -> 0 | P18: 13163 | Q18: 13000 | R18: =P18*H18 -> 235880.96 | S18: 20kg小包带托盘 | T18: 32 | U18: 4 | V18: 1 | W18: 128
A19: 毛晓翔 | B19: 全款预付 | C19: 自提 | D19: 浙江五合进出口有限公司 | E19: CHDN-20260615-304 | F19: 46218 | G19: CH520 | H19: 1.5 | I19: 15850 | J19: =H19*I19 -> 23775 | K19: 1.5 | L19: =H19-K19 -> 0 | M19: =高科收款!D60 -> 23775 | N19: =J19-M19 -> 0 | O19: =K19*I19-M19 -> 0 | P19: 15500 | Q19: 15400 | R19: =P19*H19 -> 23250 | S19: 打3托，其中2托40包 ，1 托15包 | T19: 3
A20: 张晓敏 | B20: 全款预付 | C20: 自提 | D20: 陕西杰艾恩特贸易有限公司 | E20: CHDN-20260616-305 | F20: 46219 | G20: CH301 | H20: 7 | I20: 13000 | J20: =H20*I20 -> 91000 | K20: 7 | L20: =H20-K20 -> 0 | M20: =高科收款!D63 -> 91000 | N20: =J20-M20 -> 0 | O20: =K20*I20-M20 -> 0 | P20: 13000 | Q20: 13000 | R20: =P20*H20 -> 91000 | S20: 20kg 散货包装
A21: 张晓敏 | B21: 全款预付 | C21: 自提 | D21: 浙江五合进出口有限公司 | E21: CHDN-20260629-344 | F21: 46235 | G21: CH332 | H21: 266.24 | I21: 12200 | J21: =H21*I21 -> 3248128 | K21: =61.44+61.44+61.44+40.96+40.96 -> 266.24 | L21: =H21-K21 -> 0 | M21: =741440+高科收款!D68+高科收款!D69+6688 -> 3248128 | N21: =J21-M21 -> 0 | O21: =K21*I21-M21 -> 0 | P21: 12008 | Q21: 11800 | R21: =P21*H21 -> 3197009.9 | S21: 20kg小包带托盘 | T21: 416 | U21: 26 | V21: 13 | W21: 1664
A22: 毛晓翔 | B22: 款到发货 | C22: 自提 | D22: 苏州名创新材料有限公司 | E22: CHDN-20260706-361 | F22: 46223 | G22: CH506 | H22: 5.01 | I22: 13000 | J22: =H22*I22 -> 65130 | K22: 5.01 | L22: =H22-K22 -> 0 | M22: 65130 | N22: =J22-M22 -> 0 | O22: =K22*I22-M22 -> 0 | P22: 13000 | Q22: 12750 | R22: =P22*H22 -> 65130 | S22: 15kg/包散装
A23: 毛晓翔 | B23: 款到发货 | C23: 自提 | D23: 苏州名创新材料有限公司 | E23: CHDN-20260706-361 | F23: 46223 | G23: CH510 | H23: 5.01 | I23: 13000 | J23: =H23*I23 -> 65130 | K23: 5.01 | L23: =H23-K23 -> 0 | M23: 65130 | N23: =J23-M23 -> 0 | O23: =K23*I23-M23 -> 0 | P23: 13000 | Q23: 12750 | R23: =P23*H23 -> 65130 | S23: 15kg/包散装
A24: 张晓敏 | B24: 款到发货 | C24: 送到 | D24: 临沂天佑地毯有限公司 | E24: CHDN-20260707-366 | F24: 46223 | G24: CH520 | H24: 3 | I24: 13100 | J24: =H24*I24 -> 39300 | K24: =2.865+0.135 -> 3 | L24: =H24-K24 -> 0 | M24: =高科收款!D70 -> 39300 | N24: =J24-M24 -> 0 | O24: =K24*I24-M24 -> 0 | P24: 12720 | Q24: 12600 | R24: =P24*H24 -> 38160 | S24: 15kg/包散装
A25: 张晓敏 | B25: 款到发货 | C25: 送到 | D25: 浙江五合进出口有限公司 | E25: CHDN-20260708-371 | F25: 46265 | G25: CH332 | H25: 89.32 | I25: 12000 | J25: =H25*I25 -> 1071840 | K25: =50.6+25.52+13.2 -> 89.32 | L25: =H25-K25 -> 0 | M25: =高科收款!D75+高科收款!D76 -> 1071840 | N25: =J25-M25 -> 0 | O25: =K25*I25-M25 -> 0 | P25: 11500 | Q25: 11300 | R25: =P25*H25 -> 1027180 | S25: 220kg/包，吨袋包装
A26: 毛晓翔 | B26: 款到发货 | C26: 自提 | D26: 青岛玖盈化工有限公司 | E26: CHDN-20260709-382 | F26: 46223 | G26: CH520 | H26: 0.06 | I26: 15000 | J26: =H26*I26 -> 900 | K26: 0.06 | L26: =H26-K26 -> 0 | M26: =高科收款!D78 -> 900 | N26: =J26-M26 -> 0 | O26: =K26*I26-M26 -> 0 | P26: 15000 | Q26: 12600 | R26: =P26*H26 -> 900 | S26: 15kg/包散装
A27: 毛晓翔 | B27: 100%预付 | C27: 自提 | D27: 金华穗广 | E27: CHDN-20260713-398 | F27: 46233 | G27: CH301 | H27: 153.6 | I27: 12355 | J27: =H27*I27 -> 1897728 | K27: =38.4+57.6+57.6 -> 153.6 | L27: =H27-K27 -> 0 | M27: =高科收款!D80+高科收款!D82 -> 1897728 | N27: =J27-M27 -> 0 | O27: =K27*I27-M27 -> 0 | P27: 12111 | Q27: 12100 | R27: =P27*H27 -> 1860249.6 | S27: 600公斤吨袋 | T27: 128 | V27: 8 | W27: 512 | X27: 256
A28: 张晓敏 | B28: 款到发货 | C28: 自提 | D28: 浙江五合进出口有限公司 | E28: CHDN-20260714-403 | F28: 46265 | G28: CH332 | H28: 389.12 | I28: 12200 | J28: =H28*I28 -> 4747264 | K28: =41+61.5+61.5+61.5+163.62 -> 389.12 | L28: =H28-K28 -> 0 | M28: =高科收款!D79+高科收款!D88+高科收款!D92+1765568 -> 4747264 | N28: =J28-M28 -> 0 | O28: =K28*I28-M28 -> 0 | P28: 12010 | Q28: 12000 | R28: =P28*H28 -> 4673331.2 | S28: 20kg小包带托盘 | T28: =32*20 -> 640 | U28: =2*20 -> 40 | V28: =1*20 -> 20 | W28: =128*20 -> 2560
A29: 张晓敏 | B29: 款到发货 | C29: 自提 | D29: 浙江五合进出口有限公司 | E29: CHDN-20260714-403 | F29: 46265 | G29: CH301 | H29: 19.2 | I29: 12210 | J29: =H29*I29 -> 234432 | K29: 19.2 | L29: =H29-K29 -> 0 | M29: =高科收款!D93-1765568 -> 234432 | N29: =J29-M29 -> 0 | O29: =K29*I29-M29 -> 0 | P29: 12008 | Q29: 12000 | R29: =P29*H29 -> 230553.6 | S29: 20kg小包带托盘
A30: 毛晓翔 | B30: 款到发货 | C30: 自提 | D30: 杭州塑合新材料有限公司 | E30: CHDN-20260717-429 | F30: 46225 | G30: CH301 | H30: 0.3 | I30: 14000 | J30: =H30*I30 -> 4200 | K30: 0.3 | L30: =H30-K30 -> 0 | M30: =高科收款!D87 -> 4200 | N30: =J30-M30 -> 0 | O30: =K30*I30-M30 -> 0 | P30: 14000 | Q30: 13000 | R30: =P30*H30 -> 4200 | S30: 20kg 散货包装
A31: 毛晓翔 | B31: 款到发货 | C31: 自提 | D31: 苏州名创新材料有限公司 | E31: CHDN-20260722-450 | F31: 46233 | G31: CH510 | H31: 6 | I31: 14500 | J31: =H31*I31 -> 87000 | K31: 6 | L31: =H31-K31 -> 0 | M31: 87000 | N31: =J31-M31 -> 0 | O31: =K31*I31-M31 -> 0 | P31: 14500 | Q31: 14250 | R31: =P31*H31 -> 87000 | S31: 15kg/包散装
A32: 毛晓翔 | B32: 款到发货 | C32: 自提 | D32: 金华烯谷新材料有限公司 | E32: CHDN-20260723-458 | F32: 46244 | G32: CH608 | H32: 25 | I32: 13700 | J32: =H32*I32 -> 342500 | K32: 25 | L32: =H32-K32 -> 0 | M32: =高科收款!D91 -> 342500 | N32: =J32-M32 -> 0 | O32: =K32*I32-M32 -> 0 | P32: 13700 | R32: =P32*H32 -> 342500
A33: 张晓敏 | B33: 款到发货 | C33: 送到 | D33: 浙江五合进出口有限公司 | E33: CHDN-20260723-460 | F33: 46265 | G33: CH332 | H33: 70.84 | I33: 13600 | J33: =H33*I33 -> 963424 | K33: =26.4+26.4 -> 52.8 | L33: =H33-K33 -> 18.04 | M33: =高科收款!D110 -> 963424 | N33: =J33-M33 -> 0 | O33: =K33*I33-M33 -> -245344 | P33: 13110 | Q33: 13100 | R33: =P33*H33 -> 928712.4 | S33: 220kg/包；需324个小尺寸吨袋，单价46元/个
A34: 毛晓翔 | B34: 款到发货 | C34: 自提 | D34: 金华穗广 | E34: CHDN-20260724-461 | F34: 46249 | G34: CH301 | H34: 19.2 | I34: 13350 | J34: =H34*I34 -> 256320 | K34: 19.2 | L34: =H34-K34 -> 0 | M34: =高科收款!D111 -> 256320 | N34: =J34-M34 -> 0 | O34: =K34*I34-M34 -> 0 | P34: 13110 | R34: =P34*H34 -> 251712 | S34: 20kg小包带托盘 | T34: 32 | U34: 2 | V34: 1 | W34: 64
A35: 毛晓翔 | B35: 款到发货 | C35: 自提 | D35: 无锡市中捷诚化工有限公司 | E35: CHDN-20260728-472 | F35: 46253 | G35: CH608 | H35: 27 | I35: 14000 | J35: =H35*I35 -> 378000 | K35: 27 | L35: =H35-K35 -> 0 | M35: =高科收款!D100 -> 378000 | N35: =J35-M35 -> 0 | O35: =K35*I35-M35 -> 0 | P35: 14000 | Q35: 13700 | R35: =P35*H35 -> 378000
A36: 张晓敏 | B36: 款到发货 | C36: 送到 | D36: 浙江五合进出口有限公司 | E36: CHDN-20260731-479 | F36: 46265 | G36: CH332 | H36: 0.38 | I36: 12800 | J36: =H36*I36 -> 4864 | K36: 0.38 | L36: =H36-K36 -> 0 | M36: =高科收款!D94 -> 4864 | N36: =J36-M36 -> 0 | O36: =K36*I36-M36 -> 0 | P36: 12800 | Q36: 12600 | R36: =P36*H36 -> 4864 | S36: 20kg/包，散货
A37: 毛晓翔 | B37: 款到发货 | C37: 自提 | D37: 金华穗广 | E37: CHDN-20260805-492 | F37: 46264 | G37: CH332 | H37: 34 | I37: 12100 | J37: =H37*I37 -> 411400 | K37: 34 | L37: =H37-K37 -> 0 | M37: =513300-101900 -> 411400 | N37: =J37-M37 -> 0 | O37: =K37*I37-M37 -> 0 | P37: 12100 | R37: =P37*H37 -> 411400
A38: 毛晓翔 | B38: 款到发货 | C38: 自提 | D38: 金华穗广 | E38: CHDN-20260805-492 | F38: 46264 | G38: CH520 | H38: 6 | I38: 13800 | J38: =H38*I38 -> 82800 | K38: 6 | L38: =H38-K38 -> 0 | M38: 101900 | N38: =J38-M38 -> -19100 | O38: =K38*I38-M38 -> -19100 | P38: 13800 | R38: =P38*H38 -> 82800
A39: 毛晓翔 | B39: 款到发货 | C39: 自提 | D39: 苏州名创新材料有限公司 | E39: CHDN-20260810-515 | F39: 46254 | G39: CH510 | H39: 6 | I39: 14800 | J39: =H39*I39 -> 88800 | K39: 6 | L39: =H39-K39 -> 0 | M39: 88800 | N39: =J39-M39 -> 0 | O39: =K39*I39-M39 -> 0 | P39: 14800 | Q39: 14350 | R39: =P39*H39 -> 88800 | S39: 15kg/包散装
A40: 毛晓翔 | B40: 款到发货 | C40: 自提 | D40: 苏州名创新材料有限公司 | E40: CHDN-20260810-515 | F40: 46254 | G40: CH506 | H40: 4.5 | I40: 14800 | J40: =H40*I40 -> 66600 | K40: 4.5 | L40: =H40-K40 -> 0 | M40: 66600 | N40: =J40-M40 -> 0 | O40: =K40*I40-M40 -> 0 | P40: 14800 | Q40: 14350 | R40: =P40*H40 -> 66600 | S40: 15kg/包散装
...

Sheet 高科对外
A1: 销售员 | B1: 付款方式 | C1: 单位名称 | D1: 合同号 | E1: 合同有效期 | F1: 产品规格 | G1: 合同量 | H1: 销售单价 | I1: 销售金额 | J1: 实际出库 | K1: 未发量 | L1: 到款金额 | M1: 余款 | N1: 应收款 | O1: 佣金 | P1: 佣金总金额 | Q1: 审批汇率 | R1: 出厂价 | S1: 指导价 | T1: 合同总金额￥ | U1: 包装 | V1: 运输条款 | W1: 目的港 | X1: 审批海运费 | Y1: 审批保费 | Z1: 审批内陆费 | AA1: 实际海运费 | AB1: 托盘数量 | AC1: 缠绕膜 | AD1: 扎带 | AE1: 卡扣 | AF1: 吨袋 | AG1: 绑带 | AH1: 备注 | AI1: 开票
A2: 杨玉赏 | B2: 50/50TT | C2: INABATA SINGAPORE (PTE.) LTD. | D2: CHDW-20260408-017 | E2: 46172 | F2: CH520 | G2: 75 | H2: 2860 | I2: =G2*H2 -> 214500 | J2: 0 | K2: =G2-J2 -> 75 | L2: 0 | M2: =I2-L2 -> 214500 | N2: =J2*H2-L2 -> 0 | O2: 0 | P2: =P20 -> 0 | Q2: 6.86 | R2: 20530 | S2: 20500 | T2: =R2*G2 -> 1539750 | U2: 15KG小包散装 | V2: CIF | W2: IZMIR | X2: =4*3400 -> 13600 | Y2: =4*50 -> 200 | Z2: =4*4000 -> 16000
A3: 杨玉赏 | B3: 50/50TT | C3: INABATA SINGAPORE (PTE.) LTD. | D3: CHDW-20260409-018 | E3: 46178 | F3: CH520 | G3: 56.25 | H3: 2880 | I3: =G3*H3 -> 162000 | J3: 0 | K3: =G3-J3 -> 56.25 | L3: 0 | M3: =I3-L3 -> 162000 | N3: =J3*H3-L3 -> 0 | O3: 0 | P3: =P2 -> 0 | Q3: 6.81 | R3: 20506 | S3: 20500 | T3: =R3*G3 -> 1153462.5 | U3: 15KG小包散装 | V3: CIF | W3: IZMIR | X3: =3*3400 -> 10200 | Y3: =3*50 -> 150 | Z3: =3*4500 -> 13500
A4: 张晓敏 | B4: 30/80TT | C4: EMAAR SQUARE GENERAL TRADING & CONT.CO | D4: CHDW-20260105-001 | E4: 46058 | F4: CH332 | G4: 19.2 | H4: 1720 | I4: =G4*H4 -> 33024 | J4: 19.2 | K4: =G4-J4 -> 0 | L4: =高科收款!D2+高科收款!D5 -> 32984 | M4: =I4-L4 -> 40 | N4: =J4*H4-L4 -> 40 | O4: 0 | P4: =O4*G4 -> 0 | Q4: 6.95 | R4: 12007 | S4: 11400 | T4: =R4*G4 -> 230534.4 | U4: 20kg带托盘 | V4: CIF | W4: 科威特Shuwaikh港 | X4: 2600 | Y4: 38 | Z4: 4500 | AB4: 32 | AC4: 4 | AD4: 1 | AE4: 130 | AH4: 0.8吨不执行
A5: 毛晓翔 | B5: 20/80TT | C5: LSMCHEM GLOBAL PTE. LTD. | D5: CHDW-20260108-002 | E5: 46063 | F5: CH301 | G5: 492.72 | H5: 1485 | I5: =G5*H5 -> 731689.2 | J5: =316.8+57.6+高科出库!E16+高科出库!E57+高科出库!E58+54.88 -> 492.72 | K5: =G5-J5 -> 0 | L5: =高科收款!D3+高科收款!D4 -> 741286 | M5: =I5-L5 -> -9596.8 | N5: =J5*H5-L5 -> -9596.8 | O5: 0 | P5: =O5*G5 -> 0 | Q5: 6.982 | R5: 11440 | S5: 11400 | T5: =R5*G5 -> 5636716.8 | U5: 600kg带托盘 | V5: EXW | W5: FACTORY | X5: 0 | Y5: 0 | Z5: 0 | AA5: 0 | AB5: 416 | AD5: 13 | AE5: 1664 | AF5: 832
A6: 张晓敏 | B6: 20/80TT | C6: RIYING INTERNATIONAL TRADING COMPANY LIMITED | D6: CHDW-20260113-003 | E6: 46091 | F6: CH301 | G6: 19.2 | H6: 1540 | I6: =G6*H6 -> 29568 | J6: =高科出库!E17 -> 19.2 | K6: =G6-J6 -> 0 | L6: =23960.99+5607.01 -> 29568 | M6: =I6-L6 -> 0 | N6: =J6*H6-L6 -> 0 | O6: 0 | P6: =O6*G6 -> 0 | Q6: 6.96 | R6: 11731 | S6: 11650 | T6: =R6*G6 -> 225235.2 | U6: 600kg带托盘 | V6: EXW | W6: FACTORY | X6: 0 | Y6: 0 | Z6: 0 | AA6: 0 | AB6: 32 | AD6: 1 | AE6: 128 | AF6: 32 | AH6: 18.75吨不执行
A7: 张晓敏 | B7: 30/70TT | C7: RIYING INTERNATIONAL TRADING COMPANY LIMITED | D7: CHDW-20260116-004 | E7: 46092 | F7: CH520 | G7: 37.5 | H7: 1700 | I7: =G7*H7 -> 63750 | J7: 37.5 | K7: =G7-J7 -> 0 | L7: =50936.99-5607.01+18420.02 -> 63750 | M7: =I7-L7 -> 0 | N7: =J7*H7-L7 -> 0 | O7: 0 | P7: =O7*G7 -> 0 | Q7: 6.95 | R7: 13345 | S7: 13200 | T7: =R7*G7 -> 500437.5 | U7: 15kg散装 | V7: EXW | W7: FACTORY | X7: 0 | Y7: 0 | Z7: 0 | AA7: 0
A8: 张晓敏 | B8: 30/70TT | C8: Garant-PP LTD | D8: CHDW-20260305-005 | E8: 46122 | F8: CH301 | G8: 71.68 | H8: 1732 | I8: =G8*H8 -> 124149.76 | J8: 71.68 | K8: =G8-J8 -> 0 | L8: =高科收款!D7 -> 79273.83 | M8: =I8-L8 -> 44875.93 | N8: =J8*H8-L8 -> 44875.93 | O8: 0 | P8: =O8*G8 -> 0 | Q8: 6.9 | R8: 13644 | T8: =R8*G8 -> 978001.92 | U8: 600kg吨袋 托盘包装 | V8: CIF | W8: 保加利亚Burgas | X8: =3700*4 -> 14800 | Y8: =42.4*4 -> 169.6 | Z8: =4000*4 -> 16000 | AB8: 160 | AC8: 4 | AD8: 7 | AE8: 896 | AF8: 128
A9: 张晓敏 | B9: 30/70TT | C9: Garant-PP LTD | D9: CHDW-20260305-005 | E9: 46122 | F9: CH301 | G9: =35.84+17.92 -> 53.76 | H9: 1732 | I9: =G9*H9 -> 93112.32 | J9: =35.84+17.92 -> 53.76 | K9: =G9-J9 -> 0 | L9: =高科收款!D40 -> 169922.68 | M9: =I9-L9 -> -76810.36 | N9: =J9*H9-L9 -> -76810.36 | O9: 0 | P9: =O9*G9 -> 0 | Q9: 6.9 | R9: 13695 | T9: =R9*G9 -> 736243.2 | U9: 20kg/包 托盘包装 | V9: CIF | W9: 保加利亚Burgas | X9: =3700*3 -> 11100 | Y9: =42.4*3 -> 127.2 | Z9: =4000*3 -> 12000
A10: 张晓敏 | B10: 50/50TT | C10: RIYING INTERNATIONAL TRADING COMPANY LIMITED | D10: CHDW-20260305-006 | E10: 46122 | F10: CH301 | G10: 53.76 | H10: 1770 | I10: =G10*H10 -> 95155.2 | J10: 53.76 | K10: =G10-J10 -> 0 | L10: =44990.21-18420.02+高科收款!D62 -> 94999.17 | M10: =I10-L10 -> 156.03 | N10: =J10*H10-L10 -> 156.03 | O10: 0 | P10: =O10*G10 -> 0 | Q10: 6.9 | R10: 13420 | T10: =R10*G10 -> 721459.2 | U10: 600kg 吨袋托盘包装 | V10: EXW | W10: FACTORY | X10: 0 | Y10: 0 | Z10: 0 | AA10: 0 | AB10: 96 | AD10: 3 | AE10: 384 | AF10: 96
A11: 杨玉赏 | B11: 100TT | C11: INABATA SINGAPORE (PTE.) LTD. | D11: CHDW-20260306-007 | E11: 46132 | F11: CH520 | G11: 130.56 | H11: 2290 | I11: =G11*H11 -> 298982.4 | J11: 130.56 | K11: =G11-J11 -> 0 | L11: =高科收款!D25 -> 298982.4 | M11: =I11-L11 -> 0 | N11: =J11*H11-L11 -> 0 | O11: 0 | P11: =O11*G11 -> 0 | Q11: 6.9 | R11: 15354 | S11: 15350 | T11: =R11*G11 -> 2004618.2 | U11: 15KG小包托盘 | V11: CIF | W11: GEBZE | X11: =4000*8 -> 32000 | Y11: =30*8 -> 240 | Z11: =4000*8 -> 32000 | AB11: 256 | AC11: 32 | AD11: 8 | AE11: 1040
A12: 杨玉赏 | B12: 100TT | C12: INABATA SINGAPORE (PTE.) LTD. | D12: CHDW-20260312-008 | E12: 46124 | F12: CH520 | G12: 48.96 | H12: 2405 | I12: =G12*H12 -> 117748.8 | J12: 48.96 | K12: =G12-J12 -> 0 | L12: =高科收款!D26 -> 117748.8 | M12: =I12-L12 -> 0 | N12: =J12*H12-L12 -> 0 | O12: 0 | P12: =O12*G12 -> 0 | Q12: 6.87 | R12: 16178 | S12: 16100 | T12: =R12*G12 -> 792074.88 | U12: 15KG小包托盘 | V12: CIF | W12: GEBZE | X12: =4000*3 -> 12000 | Y12: =30*3 -> 90 | Z12: =4000*3 -> 12000 | AB12: 96 | AC12: 12 | AD12: 3 | AE12: 390
A13: 张晓敏 | B13: 30/70TT | C13: CHINA UNICHEM HOLDINGS PTE LTD | D13: CHDW-20260316-009 | E13: 46122 | F13: CH520 | G13: 56.25 | H13: 2115 | I13: =G13*H13 -> 118968.75 | J13: 56.25 | K13: =G13-J13 -> 0 | L13: =高科收款!D8+83253 -> 118919 | M13: =I13-L13 -> 49.75 | N13: =J13*H13-L13 -> 49.75 | O13: 0 | P13: =O13*G13 -> 0 | Q13: 6.89 | R13: 16226 | T13: =R13*G13 -> 912712.5 | U13: 15KG小包散装 | V13: FOB | W13: NINGBO | X13: 0 | Y13: 0 | Z13: 5000 | AA13: 0
A14: 杨玉赏 | B14: 100TT | C14: INABATA SINGAPORE (PTE.) LTD. | D14: CHDW-20260318-010 | E14: 46143 | F14: CH520 | G14: 75 | H14: 2390 | I14: =G14*H14 -> 179250 | J14: =37.5+37.5 -> 75 | K14: =G14-J14 -> 0 | L14: =高科收款!D32 -> 179250 | M14: =I14-L14 -> 0 | N14: =J14*H14-L14 -> 0 | O14: 0 | P14: =O14*G14 -> 0 | Q14: 6.87 | R14: 16550 | S14: 16400 | T14: =R14*G14 -> 1241250 | U14: 15KG小包散装 | V14: CIF | W14: IZMIR | X14: =4200*4 -> 16800 | Y14: =50*4 -> 200 | Z14: =4000*4 -> 16000
A15: 陈诺 | B15: 100TT | C15: Rare International Corp. | D15: CHDW-20260320-011 | E15: 46132 | F15: CH265 | G15: 34.2 | H15: 1860 | I15: =G15*H15 -> 63612 | J15: 34.2 | K15: =G15-J15 -> 0 | L15: =高科收款!D14 -> 63612 | M15: =I15-L15 -> 0 | N15: =J15*H15-L15 -> 0 | O15: 0 | P15: =O15*G15 -> 0 | Q15: 6.87 | R15: 14024 | S15: 13700 | T15: =R15*G15 -> 479620.8 | U15: 30KG小包散装 | V15: CIF | W15: Ho Chi Minh | X15: =300*2 -> 600 | Y15: =35*2 -> 70 | Z15: =4500*2 -> 9000
A16: 陈诺 | B16: 100TT | C16: Rare International Corp. | D16: CHDW-20260323-012 | E16: 46135 | F16: CH265 | G16: 17.1 | H16: 1930 | I16: =G16*H16 -> 33003 | J16: 17.1 | K16: =G16-J16 -> 0 | L16: =高科收款!D15 -> 33003 | M16: =I16-L16 -> 0 | N16: =J16*H16-L16 -> 0 | O16: 0 | P16: =O16*G16 -> 0 | Q16: 6.87 | R16: 14000 | S16: 13700 | T16: =R16*G16 -> 239400 | U16: 30KG小包散装 | V16: CIF | W16: CHITTAGONG | X16: 1550 | Y16: 35 | Z16: 4500
A17: 陶莹 | B17: 100TT | C17: WWRC Korea Co.,Ltd | D17: CHDW-20260326-013 | E17: 46138 | F17: CH301 | G17: 35.84 | H17: 2160 | I17: =G17*H17 -> 77414.4 | J17: 35.84 | K17: =G17-J17 -> 0 | L17: 77414.4 | M17: =I17-L17 -> 0 | N17: =J17*H17-L17 -> 0 | O17: 0 | P17: =O17*G17 -> 0 | Q17: 6.89 | R17: 16167 | S17: 16100 | T17: =R17*G17 -> 579425.28 | U17: 560kg/吨包带托盘 | V17: CIF | W17: BUSAN | X17: 0 | Y17: =43*2 -> 86 | Z17: =4000*2 -> 8000 | AB17: 96 | AD17: 3 | AE17: 390 | AF17: 96 | AG17: 3
A18: 毛晓翔 | B18: 100TT | C18: PALMETTO ADHESIVES COMPANY | D18: CHDW-20260330-014 | E18: 46142 | F18: CH520 | G18: 1.68 | H18: 2780 | I18: =G18*H18 -> 4670.4 | J18: 1.68 | K18: =G18-J18 -> 0 | L18: 4670.4 | M18: =I18-L18 -> 0 | N18: =J18*H18-L18 -> 0 | O18: 0 | P18: =O18*G18 -> 0 | Q18: 6.85 | R18: 17750 | S18: 17100 | T18: =R18*G18 -> 29820 | U18: 15KG小包托盘 | V18: CIF | W18: Charleston | X18: 500 | Y18: 10 | Z18: 2000 | AB18: 4
A19: 杨玉赏 | B19: 50/50TT | C19: INABATA SINGAPORE (PTE.) LTD. | D19: CHDW-20260402-015 | E19: 46175 | F19: CH520 | G19: 97.92 | H19: 3015 | I19: =G19*H19 -> 295228.8 | J19: 97.92 | K19: =G19-J19 -> 0 | L19: =高科收款!D21+高科收款!D33 -> 295228.8 | M19: =I19-L19 -> 0 | N19: =J19*H19-L19 -> 0 | O19: 0 | P19: =O19*G19 -> 0 | Q19: 6.86 | R19: 21110 | S19: 20000 | T19: =R19*G19 -> 2067091.2 | U19: 15KG小包托盘 | V19: CIF | W19: GEBZE | X19: =6*3500 -> 21000 | Y19: =6*50 -> 300 | Z19: =4000*6 -> 24000 | AB19: 192 | AC19: 24 | AD19: 6 | AE19: 780
A20: 杨玉赏 | B20: 30/70TT | C20: SOPREMA LTDA | D20: CHDW-20260407-016 | E20: 46149 | F20: CH301 | G20: 19 | H20: 2585 | I20: =G20*H20 -> 49115 | J20: 19 | K20: =G20-J20 -> 0 | L20: =高科收款!D28+高科收款!D48 -> 49115 | M20: =I20-L20 -> 0 | N20: =J20*H20-L20 -> 0 | O20: 0 | P20: =P19 -> 0 | Q20: 6.87 | R20: 18294 | S20: 18000 | T20: =R20*G20 -> 347586 | U20: 20kg/包散装 | V20: CIF | W20: SANTOS | X20: 3700 | Y20: 50 | Z20: 4000
A21: 杨玉赏 | B21: 50/50TT | C21: INABATA SINGAPORE (PTE.) LTD. | D21: CHDW-20260414-019 | E21: 46203 | F21: CH520 | G21: 37.5 | H21: 2925 | I21: =G21*H21 -> 109687.5 | J21: 37.5 | K21: =G21-J21 -> 0 | L21: =高科收款!D27+高科收款!D43 -> 109687.5 | M21: =I21-L21 -> 0 | N21: =J21*H21-L21 -> 0 | O21: 0 | P21: =P3 -> 0 | Q21: 6.81 | R21: 20811 | S21: 20600 | T21: =R21*G21 -> 780412.5 | U21: 15KG小包散装
A22: 陈诺 | B22: 100TT | C22: Rare International Corp. | D22: CHDW-20260414-020 | E22: 46156 | F22: CH406 | G22: 9.6 | H22: 2535 | I22: =G22*H22 -> 24336 | J22: 9.6 | K22: =G22-J22 -> 0 | L22: =高科收款!D23 -> 24336 | M22: =I22-L22 -> 0 | N22: =J22*H22-L22 -> 0 | O22: 0 | P22: =P21 -> 0 | Q22: 6.8 | R22: 18370 | S22: 18000 | T22: =R22*G22 -> 176352 | U22: 20kg/包托盘 | V22: CIF | W22: TAICHUNG | X22: 525 | Y22: 27 | Z22: 4000
A23: 杨玉赏 | B23: 100TT | C23: SOPREMA LTDA | D23: CHDW-20260420-021 | E23: 46203 | F23: CH301 | G23: 19 | H23: 2620 | I23: =G23*H23 -> 49780 | J23: 19 | K23: =G23-J23 -> 0 | L23: =高科收款!D65 -> 49780 | M23: =I23-L23 -> 0 | N23: =J23*H23-L23 -> 0 | O23: 0 | P23: =P22 -> 0 | Q23: 6.8 | R23: 18324 | S23: 18000 | T23: =R23*G23 -> 348156 | U23: 20kg/包散装 | V23: CIF | W23: SANTOS | X23: 2400 | Y23: 50 | Z23: 4000
A24: 杨玉赏 | B24: 100TT | C24: INABATA SINGAPORE (PTE.) LTD. | D24: CHDW-20260509-022 | E24: 46188 | F24: CH520 | G24: 65.28 | H24: 2760 | I24: =G24*H24 -> 180172.8 | J24: =32.64+32.64 -> 65.28 | K24: =G24-J24 -> 0 | L24: =高科收款!D50 -> 180172.8 | M24: =I24-L24 -> 0 | N24: =J24*H24-L24 -> 0 | O24: 0 | P24: =P23 -> 0 | Q24: 6.79 | R24: 18299 | S24: 18000 | T24: =R24*G24 -> 1194558.7 | U24: 15KG小包托盘 | V24: CIF | W24: GEBZE | X24: =4900*3 -> 14700 | Y24: =60*3 -> 180 | Z24: =4500*3 -> 13500
A25: 毛晓翔 | B25: 100TT | C25: DONGJU M&TCORPORATION | D25: CHDW-20260519-023 | E25: 46192 | F25: CH406 | G25: 44.8 | H25: 2100 | I25: =G25*H25 -> 94080 | J25: 44.8 | K25: =G25-J25 -> 0 | L25: =高科收款!D41 -> 94060 | M25: =I25-L25 -> 20 | N25: =J25*H25-L25 -> 20 | O25: 0 | P25: =P24 -> 0 | Q25: 6.79 | R25: 15638 | S25: 14500 | T25: =R25*G25 -> 700582.4 | U25: 25kg小包托盘 | V25: CIF | W25: BUSAN | X25: =250*2 -> 500 | Y25: =52*2 -> 104 | Z25: =4500*2 -> 9000
A26: 毛晓翔 | B26: 20/80TT | C26: LSMCHEM GLOBAL PTE. LTD. | D26: CHDW-20260519-024 | E26: 46203 | F26: CH301 | G26: 111.36 | H26: 1890 | I26: =G26*H26 -> 210470.4 | J26: =92.16+19.2 -> 111.36 | K26: =G26-J26 -> 0 | L26: =高科收款!D53+高科收款!D44+162544.24-25745.48 -> 210470.4 | M26: =I26-L26 -> 0 | N26: =J26*H26-L26 -> 0 | O26: 0 | P26: =P25 -> 0 | Q26: 6.79 | R26: 14215 | S26: 14000 | T26: =R26*G26 -> 1582982.4 | U26: 560kg吨袋 | V26: EXW | W26: FACTORY | X26: 0 | Y26: 0 | Z26: 0 | AB26: 288 | AC26: 24 | AD26: 12 | AE26: 1536 | AF26: 88
A27: 毛晓翔 | B27: 20/80TT | C27: LSMCHEM GLOBAL PTE. LTD. | D27: CHDW-20260519-024 | E27: 46203 | F27: CH301 | G27: 19.2 | H27: 1890 | I27: =G27*H27 -> 36288 | J27: 19.2 | K27: =G27-J27 -> 0 | L27: =高科收款!D81-162544.24 -> 36288 | M27: =I27-L27 -> 0 | N27: =J27*H27-L27 -> 0 | O27: 0 | P27: =P26 -> 0 | Q27: 6.79 | R27: 14290 | S27: 14000 | T27: =R27*G27 -> 274368 | U27: 20kg小包带托盘 | V27: EXW | W27: FACTORY | X27: 0 | Y27: 0 | Z27: 0
A28: 毛晓翔 | B28: 20/80TT | C28: LSMCHEM GLOBAL PTE. LTD. | D28: CHDW-20260519-024 | E28: 46203 | F28: CH302 | G28: 96 | H28: 2050 | I28: =G28*H28 -> 196800 | J28: =38.4+38.4+19.2 -> 96 | K28: =G28-J28 -> 0 | L28: =高科收款!D39+25745.48+高科收款!D96 -> 196707 | M28: =I28-L28 -> 93 | N28: =J28*H28-L28 -> 93 | O28: 0 | P28: =P27 -> 0 | Q28: 6.79 | R28: 15519 | S28: 15500 | T28: =R28*G28 -> 1489824 | U28: 20kg小包带托盘 | V28: EXW | W28: FACTORY | X28: 0 | Y28: 0 | Z28: 0
A29: 陶莹 | B29: 100TT | C29: W CHEM KOREA | D29: CHDW-20260528-025 | E29: 46201 | F29: CH301 | G29: 17.92 | H29: 1880 | I29: =G29*H29 -> 33689.6 | J29: 17.92 | K29: =G29-J29 -> 0 | L29: =高科收款!D49 -> 33671.6 | M29: =I29-L29 -> 18 | N29: =J29*H29-L29 -> 18 | O29: 0 | P29: =P28 -> 0 | Q29: 6.77 | R29: 13700 | S29: 13500 | T29: =R29*G29 -> 245504 | U29: 560kg吨袋 | V29: CIF | W29: BUSAN | X29: 0 | Y29: 200 | Z29: 37 | AB29: 32 | AD29: 1 | AE29: 130 | AF29: 32 | AG29: 60
A30: 杨玉赏 | B30: 100TT | C30: SOPREMA LTDA | D30: CHDW-20260603-026 | E30: 46206 | F30: CH301 | G30: 19 | H30: 2620 | I30: =G30*H30 -> 49780 | J30: 19 | K30: =G30-J30 -> 0 | L30: =高科收款!D99 -> 49780 | M30: =I30-L30 -> 0 | N30: =J30*H30-L30 -> 0 | O30: 0 | P30: =P29 -> 0 | Q30: 6.75 | R30: 16589 | S30: 13000 | T30: =R30*G30 -> 315191 | U30: 20kg/包散装 | V30: CIF | W30: SANTOS | X30: 7600 | Y30: 60 | Z30: 5500
A31: 毛晓翔 | B31: 30/70TT | C31: PALMETTO ADHESIVES COMPANY | D31: CHDW-20260604-027 | E31: 46182 | F31: CH520 | G31: 15.36 | H31: 2765 | I31: =G31*H31 -> 42470.4 | J31: 15.36 | K31: =G31-J31 -> 0 | L31: =高科收款!D54+高科收款!D103 -> 42428.4 | M31: =I31-L31 -> 42 | N31: =J31*H31-L31 -> 42 | O31: 0 | P31: =P30 -> 0 | Q31: 6.75 | R31: 17150 | S31: 15500 | T31: =R31*G31 -> 263424 | U31: 15kg小包带托盘 | V31: CIF | W31: Charleston | X31: 6700 | Y31: 47 | Z31: 5000 | AB31: 32 | AC31: 2 | AD31: 1 | AE31: 64
A32: 陶莹 | B32: 100TT | C32: De Monchy International B.V | D32: CHDW-20260605-028 | E32: 46208 | F32: CH302 | G32: 1.2 | H32: 2060 | I32: =G32*H32 -> 2472 | J32: 1.2 | K32: =G32-J32 -> 0 | L32: =高科收款!D52 -> 2464 | M32: =I32-L32 -> 8 | N32: =J32*H32-L32 -> 8 | O32: 0 | P32: =P31 -> 0 | Q32: 6.7646 | R32: 14640 | S32: 14600 | T32: =R32*G32 -> 17568 | U32: 600kg带托盘 | V32: FOB | W32: NINGBO | X32: 0 | Y32: 0 | Z32: 1000 | AB32: 2 | AF32: 2
A33: 杨玉赏 | B33: 100TT | C33: INABATA SINGAPORE (PTE.) LTD. | D33: CHDW-20260608-029 | E33: 46211 | F33: CH301 | G33: 17.92 | H33: 1870 | I33: =G33*H33 -> 33510.4 | J33: 17.92 | K33: =G33-J33 -> 0 | L33: 33510.4 | M33: =I33-L33 -> 0 | N33: =J33*H33-L33 -> 0 | O33: 0 | P33: =P32 -> 0 | Q33: 6.77 | R33: 13266 | S33: 13000 | T33: =R33*G33 -> 237726.72 | U33: 20kg/包托盘 | V33: CIF | W33: SINGAPORE | X33: =1050 -> 1050 | Y33: =40 -> 40 | Z33: =5500 -> 5500 | AB33: 32 | AC33: 4 | AD33: 1 | AE33: 128
A34: 杨玉赏 | B34: 100TT | C34: INABATA SINGAPORE (PTE.) LTD. | D34: CHDW-20260608-030 | E34: 46211 | F34: CH520 | G34: 97.92 | H34: 2560 | I34: =G34*H34 -> 250675.2 | J34: =32.64+32.64+32.64 -> 97.92 | K34: =G34-J34 -> 0 | L34: 250675.2 | M34: =I34-L34 -> 0 | N34: =J34*H34-L34 -> 0 | O34: 0 | P34: =P33 -> 0 | Q34: 6.77 | R34: 15766 | S34: 15500 | T34: =R34*G34 -> 1543806.7 | U34: 15KG小包托盘 | V34: CIF | W34: GEBZE | X34: =6*6800 -> 40800 | Y34: =6*50 -> 300 | Z34: =6*5500 -> 33000 | AB34: 192 | AC34: 12 | AD34: 6 | AE34: 384
A35: 毛晓翔 | B35: 20/80TT | C35: LSMCHEM GLOBAL PTE. LTD. | D35: CHDW-20260608-031 | E35: 46234 | F35: CH301 | G35: 168 | H35: 1740 | I35: =G35*H35 -> 292320 | J35: =72+38.4+57.6 -> 168 | K35: =G35-J35 -> 0 | L35: =高科收款!D59+高科收款!D83+334368-184026 -> 292320 | M35: =I35-L35 -> 0 | N35: =J35*H35-L35 -> 0 | O35: 0 | P35: =P34 -> 0 | Q35: 6.77 | R35: 13044 | S35: 13000 | T35: =R35*G35 -> 2191392 | U35: 600kg吨袋 | V35: EXW | W35: FACTORY | X35: 0 | Y35: 0 | Z35: 0 | AB35: 320 | AC35: 40 | AD35: 20 | AE35: 2560 | AF35: 640
A36: 毛晓翔 | B36: 20/80TT | C36: LSMCHEM GLOBAL PTE. LTD. | D36: CHDW-20260608-031 | E36: 46234 | F36: CH332 | G36: 216 | H36: 1935 | I36: =G36*H36 -> 417960 | J36: 216 | K36: =G36-J36 -> 0 | L36: =184026+高科收款!D106+高科收款!D119 -> 417856 | M36: =I36-L36 -> 104 | N36: =J36*H36-L36 -> 104 | O36: 0 | P36: =P35 -> 0 | Q36: 6.77 | R36: 14535 | S36: 14500 | T36: =R36*G36 -> 3139560 | U36: 600kg吨袋 | V36: EXW | W36: FACTORY | X36: 0 | Y36: 0 | Z36: 0
A37: 张晓敏 | B37: 30/70TT | C37: Garant-PP LTD | D37: CHDW-20260702-032 | E37: 46236 | F37: CH301 | G37: 38.4 | H37: 2009 | I37: =G37*H37 -> 77145.6 | J37: 38.4 | K37: =G37-J37 -> 0 | L37: =23053.12+高科收款!D128 -> 77762.88 | M37: =I37-L37 -> -617.28 | N37: =高科收款!D72 -> 23053.12 | O37: 0 | P37: =P36 -> 0 | Q37: 6.77 | R37: 12057 | S37: 11900 | T37: =R37*G37 -> 462988.8 | U37: 600kg吨袋 | V37: CIF | W37: 保加利亚Burgas | X37: =7090*2 -> 14180 | Y37: =42.3*2 -> 84.6 | Z37: =4000*2 -> 8000 | AB37: 32 | AC37: 4 | AD37: 2 | AE37: 256 | AF37: 64
A38: 杨玉赏 | B38: 100TT | C38: INABATA SINGAPORE (PTE.) LTD. | D38: CHDW-20260708-033 | E38: 46265 | F38: CH520 | G38: 97.92 | H38: 2310 | I38: =G38*H38 -> 226195.2 | J38: =65.28+32.64 -> 97.92 | K38: =G38-J38 -> 0 | L38: =高科收款!D98 -> 226195.2 | M38: =I38-L38 -> 0 | N38: =J38*H38-L38 -> 0 | O38: 0 | P38: =P37 -> 0 | Q38: 6.78 | R38: 13964 | S38: 12500 | T38: =R38*G38 -> 1367354.9 | U38: 小包托盘 | V38: CIF | W38: GEBZE | X38: =6600*6 -> 39600 | Y38: =60*6 -> 360 | Z38: =5500*6 -> 33000 | AB38: 192 | AC38: 12 | AD38: 6 | AE38: 384
A39: 张晓敏 | B39: 30/70TT | C39: CHINA UNICHEM HOLDINGS PTE LTD | D39: CHDW-20260708-034 | E39: 46241 | F39: CH520 | G39: 16.32 | H39: 1725 | I39: =G39*H39 -> 28152 | J39: =高科出库!E330 -> 16.32 | K39: =G39-J39 -> 0 | L39: =高科收款!D84+高科收款!D132 -> 28102 | M39: =I39-L39 -> 50 | N39: =J39*H39-L39 -> 50 | O39: 0 | P39: =P38 -> 0 | Q39: 6.78 | R39: 12638 | S39: 12600 | T39: =R39*G39 -> 206252.16 | U39: 15kg小包带托盘 | V39: FOB | W39: NINGBO | X39: =0 -> 0 | Y39: 0 | Z39: 5500 | AB39: 32 | AC39: 2 | AD39: 1 | AE39: 128
A40: 张晓敏 | B40: 30/70TT | C40: CHINA UNICHEM HOLDINGS PTE LTD | D40: CHDW-20260714-035 | E40: 46248 | F40: CH520 | G40: 37.5 | H40: 1760 | I40: =G40*H40 -> 66000 | J40: 37.5 | K40: =G40-J40 -> 0 | L40: =高科收款!D89+高科收款!D148 -> 65950 | M40: =I40-L40 -> 50 | N40: =J40*H40-L40 -> 50 | O40: 0 | P40: =P39 -> 0 | Q40: 6.77 | R40: 13197 | S40: 13100 | T40: =R40*G40 -> 494887.5 | U40: 15kg小包散装 | V40: FOB | W40: NINGBO | X40: =0 -> 0 | Y40: 0 | Z40: =5000*2 -> 10000
...

Sheet 高科收款
A1: 日期 | B1: 客户 | C1: 合同号 | D1: 收款金额 | E1: 付款方式 | F1: 备注
A2: 46029 | B2: EMAAR SQUARE GENERAL TRADING & CONT.CO | C2: CHDW-20260105-001 | D2: 10320 | E2: TT | F2: 001 预付
A3: 46029 | B3: LSMCHEM GLOBAL PTE. LTD. | C3: CHDW-20260108-002 | D3: 148236.4 | E3: TT | F3: 002 20%预付
A4: 46085 | B4: LSMCHEM GLOBAL PTE. LTD. | C4: CHDW-20260108-002 | D4: 593049.6 | E4: TT | F4: 002 尾款
A5: 46094 | B5: EMAAR SQUARE GENERAL TRADING & CONT.CO | C5: CHDW-20260105-001 | D5: 22664 | E5: TT | F5: 001 尾款
A6: 46094 | B6: 浙江五合进出口有限公司 | C6: CHDN-20260312-106 | D6: 4402944 | E6: TT | F6: 106 货款
A7: 46097 | B7: Garant-PP LTD | C7: CHDW-20260305-005 | D7: 79273.83 | E7: TT | F7: 005 货款 | G7: 69835
A8: 46100 | B8: CHINA UNICHEM HOLDINGS PTE LTD | C8: CHDW-20260316-009 | D8: 35666 | E8: TT | F8: 009 预付
A9: 46100 | B9: 上海穗广贸易有限公司 | C9: CHDN-20260313-111 | D9: 289800 | E9: TT | F9: 111 货款
A10: 46100 | B10: 浙江五合进出口有限公司 | C10: CHDN-20260312-106 | D10: 5660928 | E10: TT | F10: 106 货款
A11: 46100 | B11: 浙江五合进出口有限公司 | C11: CHDN-20260319-133 | D11: 160000 | E11: TT | F11: 133 货款
A12: 46104 | B12: 苏州名创新材料有限公司 | C12: CHDN-20260323-160 | D12: 208800 | E12: TT | F12: 160 货款
A13: 46106 | B13: 昆山九子莲汽车隔音材料有限公司 | C13: CHDN-20260324-177 | D13: 199824 | E13: TT | F13: 177 货款
A14: 46107 | B14: Rare International Corp. | C14: CHDW-20260320-011 | D14: 63612 | E14: TT | F14: 011 全款
A15: 46107 | B15: Rare International Corp. | C15: CHDW-20260323-012 | D15: 33003 | E15: TT | F15: 012 全款
A16: 46111 | B16: PALMETTO ADHESIVES COMPANY | C16: CHDW-20260330-014 | D16: 4660.4 | E16: TT | F16: 014 全款
A17: 46111 | B17: 浙江五合进出口有限公司 | C17: CHDN-20260312-106 | D17: 2515968 | E17: TT | F17: 106 货款
A18: 46113 | B18: WWRC Korea Co.,Ltd | C18: CHDW-20260326-013 | D18: 77414.4 | E18: TT | F18: 013 全款
A19: 46122 | B19: 宁波方觉科技有限公司 | C19: CHDN-20260408-214 | D19: 787500 | E19: TT | F19: 214 货款
... A23: 46128 | B23: Rare International Corp. | C23: CHDW-20260414-020 | D23: 24336 | E23: TT | F23: 020 全款
A24: 46128 | B24: Rare International Corp. | D24: 80 | E24: TT | F24: 样品费
A25: 46132 | B25: INABATA SINGAPORE (PTE.) LTD. | C25: CHDW-20260306-007 | D25: 298982.4 | E25: TT | F25: 007 全款
A26: 46132 | B26: INABATA SINGAPORE (PTE.) LTD. | C26: CHDW-20260312-008 | D26: 117748.8 | E26: TT | F26: 008 全款
A27: 46132 | B27: INABATA SINGAPORE (PTE.) LTD. | C27: CHDW-20260414-019 | D27: =109687.5/2 -> 54843.75 | E27: TT | F27: 019 50%预付款
A28: 46139 | B28: SOPREMA LTDA | C28: CHDW-20260407-016 | D28: 14734.5 | E28: TT | F28: 016 30%预付款
A29: 46139 | B29: 宁波方觉科技有限公司 | C29: CHDN-20260408-214 | D29: 1575000 | E29: TT | F29: 214 货款
A30: 46141 | B30: 浙江五合进出口有限公司 | C30: CHDN-20260401-201 | D30: 787696 | E30: TT | F30: 201 货款
A31: 46141 | B31: 浙江五合进出口有限公司 | C31: CHDN-20260601-273 | D31: 85904 | E31: TT | F31: 273 货款
A32: 46148 | B32: INABATA SINGAPORE (PTE.) LTD. | C32: CHDW-20260318-010 | D32: 179250 | E32: TT | F32: 010 全款
A33: 46148 | B33: INABATA SINGAPORE (PTE.) LTD. | C33: CHDW-20260402-015 | D33: 147614.4 | E33: TT | F33: 015 50%尾款
A34: 46150 | B34: 浙江五合进出口有限公司 | C34: CHDN-20260325-180 | D34: 3595600 | E34: TT | F34: 180 货款
A35: 46151 | B35: 浙江五合进出口有限公司 | C35: CHDN-20260325-180 | D35: 3000000 | E35: TT | F35: 180 货款
A36: 46153 | B36: 浙江五合进出口有限公司 | C36: CHDN-20260511-234 | D36: 562400 | E36: TT | F36: 234 全款
A37: 46155 | B37: 宁波澜塑新材料有限公司 | C37: CHDN-20260513-237 | D37: 99900 | E37: TT | F37: 237 全款
A38: 46161 | B38: 金华穗广 | C38: CHDN-20260517-243 | D38: 1585000 | E38: TT | F38: 243 全款
A39: 46162 | B39: LSMCHEM GLOBAL PTE. LTD. | C39: CHDW-20260519-024 | D39: 13521.52 | E39: TT | F39: 024 预付
A40: 46162 | B40: Garant-PP LTD | C40: CHDW-20260305-005 | D40: 169922.68 | E40: TT | F40: 005 货款 | G40: 147352.08
A41: 46162 | B41: DONGJU M&TCORPORATION | C41: CHDW-20260519-023 | D41: 94060 | E41: TT | F41: 023 货款
A42: 46167 | B42: CHINA UNICHEM HOLDINGS PTE LTD | C42: CHDW-20260316-009 | D42: 83253 | E42: TT | F42: 009 70%尾款
A43: 46167 | B43: INABATA SINGAPORE (PTE.) LTD. | C43: CHDW-20260414-019 | D43: 54843.75 | E43: TT | F43: 019 50%尾款
...

Sheet 高科出库
A1: 发货日期 | B1: 客户 | C1: 产品型号 | D1: 合同号 | E1: 数量 | F1: 包装 | G1: 柜型 | H1: 提单号 | I1: 箱封号 | J1: 司机信息 | K1: 货代
A2: 46033 | B2: EMAAR SQUARE GENERAL TRADING & CONT.CO | C2: CH332 | D2: CHDW-20260105-001 | E2: 19.2 | F2: 20kg带托盘 | J2: 浙B3Y505
A3: 46037 | B3: LSMCHEM | C3: CH301 | D3: CHDW-20260108-002 | E3: 28.8 | F3: 600公斤吨袋,其中24包带托盘扎带 | J3: 苏CkB975 刘彬13291931176 320321197002273219
A4: 46038 | B4: LSMCHEM | C4: CH301 | D4: CHDW-20260108-002 | E4: 28.8 | F4: 600公斤吨袋,其中24包带托盘扎带 | J4: 梁俊超： 18868606918 车牌：豫PU1998 身份证 412728198502094916
A5: 46038 | B5: LSMCHEM | C5: CH301 | D5: CHDW-20260108-002 | E5: 28.8 | F5: 600公斤吨袋,其中24包带托盘扎带 | J5: 梁俊超： 18868606918 车牌：豫PU1998 身份证 412728198502094916
A6: 46039 | B6: LSMCHEM | C6: CH301 | D6: CHDW-20260108-002 | E6: 27 | F6: 600公斤吨袋,其中24包带托盘扎带 | J6: 梁俊超： 18868606918 车牌：豫PU1998 身份证 412728198502094916
A7: 46043 | B7: LSMCHEM | C7: CH301 | D7: CHDW-20260108-002 | E7: 30.6 | F7: 600公斤吨袋,其中24包带托盘扎带 | J7: 梁俊超： 18868606918 车牌：豫PU1998 身份证 412728198502094916
A8: 46044 | B8: LSMCHEM | C8: CH301 | D8: CHDW-20260108-002 | E8: 28.8 | F8: 600公斤吨袋,其中24包带托盘扎带 | J8: 梁俊超： 18868606918 车牌：豫PU1998 身份证 412728198502094916
A9: 46045 | B9: LSMCHEM | C9: CH301 | D9: CHDW-20260108-002 | E9: 28.8 | F9: 600公斤吨袋,其中24包带托盘扎带 | J9: 冀E4943W 黄德占 15227707078 132233197501241736
A10: 46046 | B10: LSMCHEM | C10: CH301 | D10: CHDW-20260108-002 | E10: 28.8 | F10: 600公斤吨袋,其中24包带托盘扎带 | J10: 姓名，孙杰 ， 车号 ，皖SB6150， 电话，18067531780 身份证号341223198008071358
A11: 46047 | B11: LSMCHEM | C11: CH301 | D11: CHDW-20260108-002 | E11: 28.8 | F11: 600公斤吨袋,其中24包带托盘扎带 | J11: 姓名，孙杰 ， 车号 ，皖SB6150， 电话，18067531780 身份证号341223198008071358
A12: 46048 | B12: LSMCHEM | C12: CH301 | D12: CHDW-20260108-002 | E12: 28.8 | F12: 600公斤吨袋,其中24包带托盘扎带 | J12: 车号：鲁Q782EX 姓名 孙振华 电话：18315796333 身份证：371322198107084933
A13: 46049 | B13: LSMCHEM | C13: CH301 | D13: CHDW-20260108-002 | E13: 28.8 | F13: 600公斤吨袋,其中24包带托盘扎带 | J13: 车号：鲁Q782EX 姓名 孙振华 电话：18315796333 身份证：371322198107084933
... A21: 46093 | B21: RIYING INTERNATIONAL TRADING COMPANY LIMITED | C21: CH301 | D21: CHDW-20260305-006 | E21: 17.92 | F21: 吨袋带托盘包装，标签 | J21: 浙B6T119 18667867181 鲁坤坤 412728198509150319
A22: 46098 | B22: INABATA SINGAPORE (PTE.) LTD. | C22: CH520 | D22: CHDW-20260306-007-1 | E22: 16.32 | F22: 15KG小包托盘 | G22: 40HQ | J22: 浙B3L100 司机：严定文 驾驶员手机： 15606686179
A23: 46098 | B23: INABATA SINGAPORE (PTE.) LTD. | C23: CH520 | D23: CHDW-20260306-007-1 | E23: 16.32 | F23: 15KG小包托盘 | G23: 40HQ | J23: 浙B6C895 司机：陈正春 驾驶员手机：13285843576
A24: 46099 | B24: INABATA SINGAPORE (PTE.) LTD. | C24: CH520 | D24: CHDW-20260306-007-1 | E24: 16.32 | F24: 15KG小包托盘 | G24: 40HQ | J24: 浙B6C895 司机：陈正春 驾驶员手机：13285843576
A25: 46100 | B25: CHINA UNICHEM HOLDINGS PTE LTD | C25: CH520 | D25: CHDW-20260316-009 | E25: 18.75 | F25: 15kg散装 | J25: 浙B6T119 18667867181 鲁坤坤 412728198509150319
A26: 46100 | B26: CHINA UNICHEM HOLDINGS PTE LTD | C26: CH520 | D26: CHDW-20260316-009 | E26: 18.75 | F26: 15kg散装 | J26: 车牌号：浙B3Q660 电话：15658225828 名字：邵海燕 身份证号码：412702198109106112
A27: 46101 | B27: Garant-PP LTD | C27: CH301 | D27: CHDW-20260305-005 | E27: 17.92 | F27: 600kg吨袋 托盘包装 | J27: 浙B6T119 18667867181 鲁坤坤 412728198509150319
A28: 46101 | B28: 浙江五合进出口有限公司 | C28: CH332 | D28: CHDN-20260319-133 | E28: 10 | F28: 20kg 散货包装 | J28: 车号：沪GE8678 司机:陈昌国 电话:13912555475 身份证：32092419760517027
A29: 46101 | B29: 上海穗广贸易有限公司 | C29: CH520 | D29: CHDN-20260313-111 | E29: 18 | F29: 15kg/包散装，1*40HQ. | J29: 车号： 浙B2G755 挂板： 浙B850U挂 司机： 贾新民 驾驶员手机： 18658223296
A30: 46102 | B30: INABATA SINGAPORE (PTE.) LTD. | C30: CH520 | D30: CHDW-20260306-007-2 | E30: 16.32 | F30: 小包带托盘 | J30: 浙B6C895 司机：陈正春 驾驶员手机：13285843576
A31: 46102 | B31: INABATA SINGAPORE (PTE.) LTD. | C31: CH520 | D31: CHDW-20260306-007-2 | E31: 16.32 | F31: 小包带托盘 | J31: 浙B2L600 司机：徐明 驾驶员手机：13685703550
A32: 46102 | B32: INABATA SINGAPORE (PTE.) LTD. | C32: CH520 | D32: CHDW-20260306-007-2 | E32: 16.32 | F32: 小包带托盘 | J32: 浙B6C895 司机：陈正春 驾驶员手机：13285843576
A33: 46102 | B33: Garant-PP LTD | C33: CH301 | D33: CHDW-20260305-005 | E33: 17.92 | F33: 600kg吨袋 托盘包装 | J33: 浙B5W781 潘宁宁 341221198409041536 18712565866
A34: 46102 | B34: Garant-PP LTD | C34: CH301 | D34: CHDW-20260305-005 | E34: 17.92 | F34: 600kg吨袋 托盘包装 | J34: 浙B6T119 18667867181 鲁坤坤 412728198509150319
A35: 46103 | B35: INABATA SINGAPORE (PTE.) LTD. | C35: CH520 | D35: CHDW-20260306-007-2 | E35: 16.32 | F35: 小包带托盘 | J35: 浙B6C895 司机：陈正春 驾驶员手机：13285843576
A36: 46103 | B36: INABATA SINGAPORE (PTE.) LTD. | C36: CH520 | D36: CHDW-20260306-007-2 | E36: 16.32 | F36: 小包带托盘 | J36: 浙B5Y686 司机：刘传付 驾驶员手机：17606836522
... A52: 46115 | B52: PALMETTO ADHESIVES COMPANY | C52: CH520 | D52: CHDW-20260330-014 | E52: 1.68 | F52: 15KG小包托盘 | J52: 司机：羊平 车牌：浙G28PA0 电话：18248539676 身份证：510722197506132878
A53: 46120 | B53: WWRC Korea Co.,Ltd | C53: CH301 | D53: CHDW-20260326-013 | E53: 17.92 | J53: 车号1：浙B6M365 车挂：浙BOX09挂 司机： 付彬 手机：15726830365 身份证 341226199210052330
A54: 46120 | B54: WWRC Korea Co.,Ltd | C54: CH301 | D54: CHDW-20260326-013 | E54: 17.92 | J54: 车号2:浙B5P332 电话 18856907101 名字 蔡自明 身份证 340121198210155513
A55: 46121 | B55: INABATA SINGAPORE (PTE.) LTD. | C55: CH520 | D55: CHDW-20260318-010 | E55: 18.75 | F55: 15KG小包托盘 | J55: 车号：浙B6M365 车挂：浙BOX09挂 司机：付彬 驾驶员手机：15726830365 身份证: 341226199210052330
A56: 46121 | B56: INABATA SINGAPORE (PTE.) LTD. | C56: CH520 | D56: CHDW-20260318-010 | E56: 18.75 | F56: 15KG小包托盘 | J56: 车号：浙B6M333/浙B0Z67挂/ 司机：陈保超 驾驶员手机：18606877698 身份证：342128197304151793
A57: 46127 | B57: LSMCHEM GLOBAL PTE. LTD. | C57: CH301 | D57: CHDW-20260108-002 | E57: 17.92 | F57: 560公斤一包 | J57: 浙B3D319 15656199969 吴志强 340621198412181219
A58: 46128 | B58: LSMCHEM GLOBAL PTE. LTD. | C58: CH301 | D58: CHDW-20260108-002 | E58: 17.92 | F58: 560公斤一包 | J58: 车号： 浙B31260D 司机： 郭堂发 驾驶员手机： 18755056551 司机身份证号： 342324197109181415
A59: 46128 | B59: 宁波方觉科技有限公司 | C59: CH520 | D59: CHDN-20260408-214 | E59: 18.75 | F59: 15kg/包散装 | J59: 司机：侯可喜 电话：17606557345 车号：浙 B7J662 身份证码：370827199508253219
A60: 46128 | B60: 宁波方觉科技有限公司 | C60: CH520 | D60: CHDN-20260408-214 | E60: 18.75 | F60: 15kg/包散装 | J60: 司机：侯可喜 电话：17606557345 车号：浙 B7J662 身份证码：370827199508253219
A61: 46128 | B61: 宁波方觉科技有限公司 | C61: CH520 | D61: CHDN-20260408-214 | E61: 18.75 | F61: 15kg/包散装 | J61: 司机：侯可喜 电话：17606557345 车号：浙 B7J662 身份证码：370827199508253219
A62: 46128 | B62: 宁波方觉科技有限公司 | C62: CH520 | D62: CHDN-20260408-214 | E62: 18.75 | F62: 15kg/包散装 | J62: 司机：江传宝 电话：15558257272 车号：浙 B3K535 身份证码：370828197910231613
...

Sheet 生物
A1: 销售员 | B1: 付款方式 | C1: 单位名称 | D1: 合同号 | E1: 合同有效期 | F1: 产品规格 | G1: 合同量 | H1: 销售单价 | I1: 销售金额 | J1: 实际出库 | K1: 未发量 | L1: 到款金额 | M1: 余款 | N1: 应收款 | O1: 佣金单价 | P1: 佣金总金额 | Q1: 审批汇率 | R1: 审批价 | S1: 指导价 | T1: 合同总金额￥ | U1: 包装 | V1: 运输条款 | W1: 目的港 | X1: 审批海运费 | Y1: 审批保费 | Z1: 审批内陆费 | AA1: 实际海运费 | AB1: 托盘数量 | AC1: 缠绕膜 | AD1: 扎带 | AE1: 卡扣 | AF1: 吨袋 | AG1: 绑带
A2: 张晓敏 | B2: 100TT | C2: FIREMAX(CAMBODIA)TIRES CO.. LTD | D2: ZJCHDW-20260121-002 | E2: 46081 | F2: N326 | G2: 478 | H2: 975 | I2: =G2*H2 -> 466050 | J2: 0 | K2: =G2-J2 -> 478 | L2: 0 | M2: =I2-L2 -> 466050 | N2: =J2*H2-L2 -> 0 | O2: 0 | P2: =O2*G2 -> 0 | Q2: 7.066 | R2: 5131 | S2: 7701 | T2: =R2*G2 -> 2452618 | U2: 1000kg 吨袋，22吨1个柜子 | V2: CIF | W2: 胡志明市 | X2: 1000 | Y2: 0 | Z2: 3500
A3: 毛晓翔 | B3: LC90 | C3: Synergy Industriez | D3: ZJCHDW-20260401-016 | E3: 46144 | F3: CH811 | G3: 82.5 | H3: 1400 | I3: =G3*H3 -> 115500 | J3: 0 | K3: =G3-J3 -> 82.5 | L3: 0 | M3: =I3-L3 -> 115500 | N3: =J3*H3-L3 -> 0 | O3: 5 | P3: =O3*G3 -> 412.5 | Q3: 6.8624 | R3: 10233 | S3: 未定指导价 | T3: =R3*G3 -> 844222.5 | U3: 25kg/bag，散装 | V3: CIF | W3: HNHAVA SHEVA | X3: =1400*3 -> 4200 | Y3: =43*3 -> 129 | Z3: =5000*3 -> 15000
A4: 杨玉赏 | B4: 100TT | C4: EUROPEAN PLASTIC JOINT STOCK COMPANY | D4: ZJCHDW-20260119-001 | E4: 46072 | F4: CH810 | G4: 5 | H4: 1035 | I4: =G4*H4 -> 5175 | J4: 5 | K4: =G4-J4 -> 0 | L4: =生物收款!E2 -> 5175 | M4: =I4-L4 -> 0 | N4: =J4*H4-L4 -> 0 | O4: 0 | P4: =O4*G4 -> 0 | Q4: 6.96 | R4: 7704 | S4: 7700 | T4: =R4*G4 -> 38520 | U4: 25kg/bag，托盘包装，1吨1托 | V4: CIF | W4: Hai Phong | X4: 0 | Y4: 10 | Z4: 1800 | AB4: 5
A5: 毛晓翔 | B5: LC90 | C5: RAI INNOTECH POLYMERS PVT. LTD. | D5: ZJCHDW-20260122-003 | E5: 46075 | F5: CH812 | G5: 82.5 | H5: 1020 | I5: =G5*H5 -> 84150 | J5: 82.5 | K5: =G5-J5 -> 0 | L5: =生物收款!E11 -> 84150 | M5: =I5-L5 -> 0 | N5: =J5*H5-L5 -> 0 | O5: 5 | P5: =O5*G5 -> 412.5 | Q5: 6.9473 | R5: 7525 | S5: 未定指导价 | T5: =R5*G5 -> 620812.5 | U5: 25kg/bag，散装 | V5: CIF | W5: MUNDRA | X5: =900*3 -> 2700 | Y5: =31*3 -> 93 | Z5: =5000*3 -> 15000
A6: 毛晓翔 | B6: LC90 | C6: D.R.PLASTO TECH PRIVATE LIMITED | D6: ZJCHDW-20260211-004 | E6: 46078 | F6: CH883 | G6: 110 | H6: 1030 | I6: =G6*H6 -> 113300 | J6: 110 | K6: =G6-J6 -> 0 | L6: =生物收款!E29 -> 113300 | M6: =I6-L6 -> 0 | N6: =J6*H6-L6 -> 0 | O6: 0 | P6: =O6*G6 -> 0 | Q6: 6.91 | R6: 7642 | S6: 未定指导价 | T6: =R6*G6 -> 840620 | U6: 25kg/bag，散装 | V6: CIF | W6: MUNDRA | X6: =800*4 -> 3200 | Y6: =31*4 -> 124 | Z6: =4500*4 -> 18000
A7: 毛晓翔 | B7: LC90 | C7: Synergy Industriez | D7: ZJCHDW-20260211-005 | E7: 46078 | F7: CH811 | G7: 82.5 | H7: 1030 | I7: =G7*H7 -> 84975 | J7: 82.5 | K7: =G7-J7 -> 0 | L7: =生物收款!E32 -> 84975 | M7: =I7-L7 -> 0 | N7: =J7*H7-L7 -> 0 | O7: 0 | P7: =O7*G7 -> 0 | Q7: 6.91 | R7: 7642 | S7: 未定指导价 | T7: =R7*G7 -> 630465 | U7: 25kg/bag，散装 | V7: CIF | W7: NHAVA SHEVA | X7: =800*3 -> 2400 | Y7: =31*3 -> 93 | Z7: =4500*3 -> 13500
A8: 毛晓翔 | B8: LC90 | C8: G P FLEX (INDIA) | D8: ZJCHDW-20260211-006 | E8: 46078 | F8: CH810 | G8: 55 | H8: 1030 | I8: =G8*H8 -> 56650 | J8: 55 | K8: =G8-J8 -> 0 | L8: =生物收款!E27 -> 56650 | M8: =I8-L8 -> 0 | N8: =J8*H8-L8 -> 0 | O8: 0 | P8: =O8*G8 -> 0 | Q8: 6.91 | R8: 7642 | S8: 未定指导价 | T8: =R8*G8 -> 420310 | U8: 25kg/bag，散装 | V8: CIF | W8: NHAVA SHEVA | X8: =800*2 -> 1600 | Y8: =31*2 -> 62 | Z8: =4500*2 -> 9000
A9: 毛晓翔 | B9: LC90 | C9: RAI INNOTECH POLYMERS PVT. LTD. | D9: ZJCHDW-20260211-007 | E9: 46078 | F9: CH812 | G9: 55 | H9: 1030 | I9: =G9*H9 -> 56650 | J9: 55 | K9: =G9-J9 -> 0 | L9: =生物收款!E30 -> 56650 | M9: =I9-L9 -> 0 | N9: =J9*H9-L9 -> 0 | O9: 0 | P9: =O9*G9 -> 0 | Q9: 6.91 | R9: 7642 | S9: 未定指导价 | T9: =R9*G9 -> 420310 | U9: 25kg/bag，散装 | V9: CIF | W9: MUNDRA | X9: =800*2 -> 1600 | Y9: =31*2 -> 62 | Z9: =4500*2 -> 9000
A10: 毛晓翔 | B10: 20/80TT | C10: AMAZON CORPORATE SERVICES PVT. LTD. | D10: ZJCHDW-20260211-008 | E10: 46078 | F10: CH810 | G10: 27.5 | H10: 1025 | I10: =G10*H10 -> 28187.5 | J10: 27.5 | K10: =G10-J10 -> 0 | L10: =生物收款!E3+16832.5 -> 28037.5 | M10: =I10-L10 -> 150 | N10: =J10*H10-L10 -> 150 | O10: 0 | P10: =O10*G10 -> 0 | Q10: 6.91 | R10: 7603 | S10: 未定指导价 | T10: =R10*G10 -> 209082.5 | U10: 25kg/bag，散装 | V10: CIF | W10: MUNDRA, FINAL ICD DADRI | X10: =800 -> 800 | Y10: =31 -> 31 | Z10: =4500 -> 4500
A11: 毛晓翔 | B11: 20/80TT | C11: AMAZON CORPORATE SERVICES PVT. LTD. | D11: ZJCHDW-20260211-008 | E11: 46078 | F11: CH811 | G11: 27.5 | H11: 1025 | I11: =G11*H11 -> 28187.5 | J11: 27.5 | K11: =G11-J11 -> 0 | L11: =生物收款!E12+生物收款!E14-16832.5 -> 28187.5 | M11: =I11-L11 -> 0 | N11: =J11*H11-L11 -> 0 | O11: 0 | P11: =O11*G11 -> 0 | Q11: 6.91 | R11: 7603 | S11: 未定指导价 | T11: =R11*G11 -> 209082.5 | U11: 25kg/bag，散装 | V11: CIF | W11: MUNDRA, FINAL ICD DADRI | X11: =800 -> 800 | Y11: =31 -> 31 | Z11: =4500 -> 4500
A12: 杨玉赏 | B12: 100TT | C12: DARU COMMERCE CO., LTD. | D12: ZJCHDW-20260305-009 | E12: 46117 | F12: CH812 | G12: 20 | H12: 1165 | I12: =G12*H12 -> 23300 | J12: 20 | K12: =G12-J12 -> 0 | L12: =生物收款!E4+生物收款!E5 -> 23300 | M12: =I12-L12 -> 0 | N12: =J12*H12-L12 -> 0 | O12: 0 | P12: =O12*G12 -> 0 | Q12: 6.87 | R12: 8810 | S12: 未定指导价 | T12: =R12*G12 -> 176200 | U12: 1000KG/包，2包共用1个托盘，20吨/20尺小柜 | V12: CFR | W12: BUSAN | X12: 10 | Y12: 0 | Z12: 4000 | AB12: 10
A13: 杨玉赏 | B13: LC90 | C13: ABBEY VIETNAM JOINT STOCK COMPANY | D13: ZJCHDW-20260310-010 | E13: 46122 | F13: N326 | G13: 234 | H13: 1089 | I13: =G13*H13 -> 254826 | J13: 234 | K13: =G13-J13 -> 0 | L13: =生物收款!E13 -> 254227.71 | M13: =I13-L13 -> 598.29 | N13: =J13*H13-L13 -> 598.29 | O13: 0 | P13: =O13*G13 -> 0 | Q13: 6.875 | R13: 7204 | S13: 7050 | T13: =R13*G13 -> 1685736 | U13: 20公斤带托盘 | V13: CIF | W13: Hai Phong | X13: =250*10 -> 2500 | Y13: =30*10 -> 300 | Z13: =4000*10 -> 40000
A14: 张晓敏 | B14: 20/80TT | C14: Valutrans Investment Co., Limited | D14: ZJCHDW-20260312-011 | E14: 46152 | F14: N330 | G14: 80 | H14: 1055 | I14: =G14*H14 -> 84400 | J14: 80 | K14: =G14-J14 -> 0 | L14: =生物收款!E17 -> 84400 | M14: =I14-L14 -> 0 | N14: =J14*H14-L14 -> 0 | O14: 0 | P14: =O14*G14 -> 0 | Q14: 6.875 | R14: 7253 | S14: 7250 | T14: =R14*G14 -> 580240 | U14: 1000kg带托盘 | V14: EXW | W14: FACTORY | X14: 0 | Y14: 0 | Z14: 0 | AA14: 0
A15: 杨玉赏 | B15: 30/70TT | C15: DARU COMMERCE CO., LTD. | D15: ZJCHDW-20260313-012 | E15: 46125 | F15: CH812 | G15: 20 | H15: 1510 | I15: =G15*H15 -> 30200 | J15: 20 | K15: =G15-J15 -> 0 | L15: =生物收款!E6+生物收款!E8 -> 30200 | M15: =I15-L15 -> 0 | N15: =J15*H15-L15 -> 0 | O15: 0 | P15: =O15*G15 -> 0 | Q15: 6.87 | R15: 11488 | S15: 未定指导价 | T15: =R15*G15 -> 229760 | U15: 1000KG/包，2包共用1个托盘，20吨/20尺小柜 | V15: CIF | W15: BUSAN | X15: 10 | Y15: 10 | Z15: 4000 | AB15: 10
A16: 杨玉赏 | B16: 100TT | C16: Polyram Plastic Industries LTD | D16: ZJCHDW-20260316-013 | E16: 46128 | F16: CH875 | G16: 5 | H16: 1560 | I16: =G16*H16 -> 7800 | J16: 5 | K16: =G16-J16 -> 0 | L16: =生物收款!E7-34320 -> 7800 | M16: =I16-L16 -> 0 | N16: =J16*H16-L16 -> 0 | O16: 30 | P16: =O16*G16 -> 150 | Q16: 6.89 | R16: 10616 | S16: 未定指导价 | T16: =R16*G16 -> 53080 | U16: 1000KG吨包带托盘 | V16: CIF | W16: HAIFA | X16: 3850 | Y16: 50 | Z16: 4500
A17: 杨玉赏 | B17: 100TT | C17: Polyram Plastic Industries LTD | D17: ZJCHDW-20260316-013 | E17: 46128 | F17: CH810 | G17: 22 | H17: 1560 | I17: =G17*H17 -> 34320 | J17: 22 | K17: =G17-J17 -> 0 | L17: 34320 | M17: =I17-L17 -> 0 | N17: =J17*H17-L17 -> 0 | O17: 30 | P17: =O17*G17 -> 660 | Q17: 6.89 | R17: 10616 | S17: 未定指导价 | T17: =R17*G17 -> 233552 | U17: 1000KG吨包带托盘 | V17: CIF | W17: HAIFA | X17: 0 | Y17: 0 | Z17: 0
A18: 杨玉赏 | B18: LC60 | C18: ABBEY VIETNAM JOINT STOCK COMPANY | D18: ZJCHDW-20260323-014 | E18: 46173 | F18: N326 | G18: 327.6 | H18: 1110 | I18: =G18*H18 -> 363636 | J18: =117+117+93.6 -> 327.6 | K18: =G18-J18 -> 0 | L18: =生物收款!E19 -> 363636 | M18: =I18-L18 -> 0 | N18: =J18*H18-L18 -> 0 | O18: 0 | P18: =O18*G18 -> 0 | Q18: 6.89 | R18: 7379 | S18: 7150 | T18: =R18*G18 -> 2417360.4 | U18: 20公斤带托盘 | V18: CIF | W18: Hai Phong | X18: =300*14 -> 4200 | Y18: =30*14 -> 420 | Z18: =4000*14 -> 56000
A19: 毛晓翔 | B19: LC90 | C19: D.R.PLASTO TECH PRIVATE LIMITED | D19: ZJCHDW-20260401-015 | E19: 46144 | F19: CH883 | G19: 55 | H19: 1400 | I19: =G19*H19 -> 77000 | J19: 55 | K19: =G19-J19 -> 0 | L19: =生物收款!E28 -> 77000 | M19: =I19-L19 -> 0 | N19: =J19*H19-L19 -> 0 | O19: 5 | P19: =O19*G19 -> 275 | Q19: 6.8624 | R19: 10233 | S19: 未定指导价 | T19: =R19*G19 -> 562815 | U19: 25kg/bag，散装 | V19: CIF | W19: MUNDRA | X19: =1400*2 -> 2800 | Y19: =43*2 -> 86 | Z19: =5000*2 -> 10000
A20: 毛晓翔 | B20: LC90 | C20: G P FLEX (INDIA) | D20: ZJCHDW-20260401-017 | E20: 46144 | F20: CH810 | G20: 55 | H20: 1400 | I20: =G20*H20 -> 77000 | J20: 55 | K20: =G20-J20 -> 0 | L20: =生物收款!E26 -> 77000 | M20: =I20-L20 -> 0 | N20: =J20*H20-L20 -> 0 | O20: 5 | P20: =O20*G20 -> 275 | Q20: 6.8624 | R20: 10233 | S20: 未定指导价 | T20: =R20*G20 -> 562815 | U20: 25kg/bag，散装 | V20: CIF | W20: NHAVA SHEVA | X20: =1400*2 -> 2800 | Y20: =43*2 -> 86 | Z20: =5000*2 -> 10000
A21: 毛晓翔 | B21: LC90 | C21: RAI INNOTECH POLYMERS PVT. LTD. | D21: ZJCHDW-20260401-018 | E21: 46144 | F21: CH812 | G21: 55 | H21: 1400 | I21: =G21*H21 -> 77000 | J21: 55 | K21: =G21-J21 -> 0 | L21: =生物收款!E23 -> 77000 | M21: =I21-L21 -> 0 | N21: =J21*H21-L21 -> 0 | O21: 5 | P21: =O21*G21 -> 275 | Q21: 6.8624 | R21: 10233 | S21: 未定指导价 | T21: =R21*G21 -> 562815 | U21: 25kg/bag，散装 | V21: CIF | W21: MUNDRA | X21: =1400*2 -> 2800 | Y21: =43*2 -> 86 | Z21: =5000*2 -> 10000
A22: 毛晓翔 | B22: LC90 | C22: AMAZON CORPORATE SERVICES PVT. LTD. | D22: ZJCHDW-20260401-019 | E22: 46144 | F22: CH811 | G22: 55 | H22: 1400 | I22: =G22*H22 -> 77000 | J22: 55 | K22: =G22-J22 -> 0 | L22: =生物收款!E20+生物收款!E25 -> 77000 | M22: =I22-L22 -> 0 | N22: =J22*H22-L22 -> 0 | O22: 5 | P22: =O22*G22 -> 275 | Q22: 6.8624 | R22: 10233 | S22: 未定指导价 | T22: =R22*G22 -> 562815 | U22: 25kg/bag，散装 | V22: CIF | W22: MUNDRA, FINAL ICD DADRI | X22: =1400*2 -> 2800 | Y22: =43*2 -> 86 | Z22: =5000*2 -> 10000
A23: 毛晓翔 | B23: LC90 | C23: ARLON INNOVATION BHARAT PRIVATE LIMITED | D23: ZJCHDW-20260408-020 | E23: 46150 | F23: CH811 | G23: 55 | H23: 1480 | I23: =G23*H23 -> 81400 | J23: 55 | K23: =G23-J23 -> 0 | L23: =生物收款!E33 -> 81400 | M23: =I23-L23 -> 0 | N23: =J23*H23-L23 -> 0 | O23: 10 | P23: =O23*G23 -> 550 | Q23: 6.816 | R23: 10730 | S23: 未定指导价 | T23: =R23*G23 -> 590150 | U23: 25kg/bag，散装 | V23: CIF | W23: MUNDRA | X23: =2*1450 -> 2900 | Y23: =2*45 -> 90 | Z23: =2*5000 -> 10000
A24: 毛晓翔 | B24: LC90 | C24: BOMBAY PLASTIC UDYOG | D24: ZJCHDW-20260408-021 | E24: 46150 | F24: CH883 | G24: 27.5 | H24: 1470 | I24: =G24*H24 -> 40425 | J24: 27.5 | K24: =G24-J24 -> 0 | L24: =生物收款!E21 -> 40425 | M24: =I24-L24 -> 0 | N24: =J24*H24-L24 -> 0 | O24: 10 | P24: =O24*G24 -> 275 | Q24: 6.816 | R24: 10653 | S24: 未定指导价 | T24: =R24*G24 -> 292957.5 | U24: 25kg/bag，散装 | V24: CIF | W24: MUNDRA | X24: =1450 -> 1450 | Y24: =45 -> 45 | Z24: =5000 -> 5000
A25: 杨玉赏 | B25: 100TT | C25: Polyram Plastic Industries LTD | D25: ZJCHDW-20260428-022 | E25: 46203 | F25: CH810 | G25: 54 | H25: 1495 | I25: =G25*H25 -> 80730 | J25: 54 | K25: =G25-J25 -> 0 | L25: =生物收款!E10 -> 80730 | M25: =I25-L25 -> 0 | N25: =J25*H25-L25 -> 0 | O25: 30 | P25: =O25*G25 -> 1620 | Q25: 6.82 | R25: 10130 | T25: =R25*G25 -> 547020 | U25: 1000KG吨包带托盘 | V25: CIF | W25: HAIFA | X25: =3400*2 -> 6800 | Y25: =50*2 -> 100 | Z25: =4500*2 -> 9000
A26: 毛晓翔 | B26: LC90 | C26: RAI INNOTECH POLYMERS PVT. LTD. | D26: ZJCHDW-20260428-023 | E26: 46178 | F26: CH812 | G26: 55 | H26: 1350 | I26: =G26*H26 -> 74250 | J26: =27.5+27.5 -> 55 | K26: =G26-J26 -> 0 | L26: 74250 | M26: =I26-L26 -> 0 | N26: =J26*H26-L26 -> 0 | O26: 5 | P26: =O26*G26 -> 275 | Q26: 6.8177 | R26: 9844 | T26: =R26*G26 -> 541420 | U26: 25kg/bag，散装 | V26: CIF | W26: MUNDRA | X26: =1200*2 -> 2400 | Y26: =41*2 -> 82 | Z26: =4800*2 -> 9600
A27: 毛晓翔 | B27: LC90 | C27: G.P. FLEX (INDIA) | D27: ZJCHDW-20260428-024 | E27: 46178 | F27: CH810 | G27: 27.5 | H27: 1350 | I27: =G27*H27 -> 37125 | J27: 27.5 | K27: =G27-J27 -> 0 | L27: =37125 -> 37125 | M27: =I27-L27 -> 0 | N27: =J27*H27-L27 -> 0 | O27: 5 | P27: =O27*G27 -> 137.5 | Q27: 6.8177 | R27: 9844 | T27: =R27*G27 -> 270710 | U27: 25kg/bag，散装 | V27: CIF | W27: HNHAVA SHEVA | X27: =1200 -> 1200 | Y27: =41 -> 41 | Z27: =4800 -> 4800
A28: 毛晓翔 | B28: LC90 | C28: G.P. FLEX (INDIA) | D28: ZJCHDW-20260428-024 | E28: 46178 | F28: CH811 | G28: 27.5 | H28: 1350 | I28: =G28*H28 -> 37125 | J28: 27.5 | K28: =G28-J28 -> 0 | L28: 37125 | M28: =I28-L28 -> 0 | N28: =J28*H28-L28 -> 0 | O28: 5 | P28: =O28*G28 -> 137.5 | Q28: 6.8177 | R28: 9844 | T28: =R28*G28 -> 270710 | U28: 25kg/bag，散装 | V28: CIF | W28: HNHAVA SHEVA | X28: =1200 -> 1200 | Y28: =41 -> 41 | Z28: =4800 -> 4800
A29: 陶莹 | B29: 30/70TT | C29: KALAY DO BRASIL LTDA | D29: ZJCHDW-20260428-025 | E29: 46170 | F29: CH810 | G29: 27 | H29: 1330 | I29: =G29*H29 -> 35910 | J29: 27 | K29: =G29-J29 -> 0 | L29: =生物收款!E9+生物收款!E16 -> 35910 | M29: =I29-L29 -> 0 | N29: =J29*H29-L29 -> 0 | O29: 0 | P29: =O29*G29 -> 0 | Q29: 6.81 | R29: 10000 | S29: 9850 | T29: =R29*G29 -> 270000 | U29: 1000kg带托盘 | V29: FOB | W29: NINGBO | X29: 0 | Y29: 0 | Z29: 5500
A30: 陶莹 | B30: 100TT | C30: RIGHT GLOBAL ADVANCED CO., LIMITED | D30: ZJCHDW-20260428-026 | E30: 46170 | F30: CH883 | G30: 10 | H30: 1370 | I30: =G30*H30 -> 13700 | J30: 10 | K30: =G30-J30 -> 0 | L30: =生物收款!E15 -> 13700 | M30: =I30-L30 -> 0 | N30: =J30*H30-L30 -> 0 | O30: 0 | P30: =O30*G30 -> 0 | Q30: 6.81 | R30: 9971 | S30: 9850 | T30: =R30*G30 -> 99710 | U30: 1000kg带托盘 | V30: CIF | W30: BUSAN | X30: =0 -> 0 | Y30: 15 | Z30: 5000
A31: 毛晓翔 | B31: LC90 | C31: BOMBAY PLASTIC UDYOG | D31: ZJCHDW-20260511-027 | E31: 46184 | F31: CH810 | G31: 27.5 | H31: 1400 | I31: =G31*H31 -> 38500 | J31: 27.5 | K31: =G31-J31 -> 0 | L31: 38500 | M31: =I31-L31 -> 0 | N31: =J31*H31-L31 -> 0 | O31: 10 | P31: =O31*G31 -> 275 | Q31: 6.7826 | R31: 10092 | T31: =R31*G31 -> 277530 | U31: 25kg/bag，散装 | V31: CIF | W31: MUNDRA | X31: 1350 | Y31: 45 | Z31: 5000
A32: 毛晓翔 | B32: LC90 | C32: BOMBAY PLASTIC UDYOG | D32: ZJCHDW-20260511-027 | E32: 46184 | F32: CH811 | G32: 27.5 | H32: 1400 | I32: =G32*H32 -> 38500 | J32: 27.5 | K32: =G32-J32 -> 0 | L32: 38500 | M32: =I32-L32 -> 0 | N32: =J32*H32-L32 -> 0 | O32: 10 | P32: =O32*G32 -> 275 | Q32: 6.7826 | R32: 10092 | T32: =R32*G32 -> 277530 | U32: 25kg/bag，散装 | V32: CIF | W32: MUNDRA | X32: 1350 | Y32: 45 | Z32: 5000
A33: 毛晓翔 | B33: LC90 | C33: SKB INDUSTRIES | D33: ZJCHDW-20260513-028 | E33: 46186 | F33: CH810 | G33: 13.5 | H33: 1350 | I33: =G33*H33 -> 18225 | J33: 13.5 | K33: =G33-J33 -> 0 | L33: 18225 | M33: =I33-L33 -> 0 | N33: =J33*H33-L33 -> 0 | O33: 0 | P33: =O33*G33 -> 0 | Q33: 6.7826 | R33: 9735 | T33: =R33*G33 -> 131422.5 | U33: 25kg/bag，散装 | V33: CIF | W33: MUNDRA | X33: 1500 | Y33: 41 | Z33: 5000
A34: 毛晓翔 | B34: LC90 | C34: SKB INDUSTRIES | D34: ZJCHDW-20260513-028 | E34: 46186 | F34: CH811 | G34: 14 | H34: 1350 | I34: =G34*H34 -> 18900 | J34: 14 | K34: =G34-J34 -> 0 | L34: 18900 | M34: =I34-L34 -> 0 | N34: =J34*H34-L34 -> 0 | O34: 0 | P34: =O34*G34 -> 0 | Q34: 6.7826 | R34: 9735 | T34: =R34*G34 -> 136290 | U34: 25kg/bag，散装 | V34: CIF | W34: MUNDRA | Y34: 42 | Z34: 5001
A35: 毛晓翔 | B35: LC90 | C35: RAI INNOTECH POLYMERS PVT. LTD. | D35: ZJCHDW-20260602-029 | E35: 46205 | F35: CH812 | G35: 110 | H35: 1400 | I35: =G35*H35 -> 154000 | J35: 110 | K35: =G35-J35 -> 0 | L35: =生物收款!E39 -> 154000 | M35: =I35-L35 -> 0 | N35: =J35*H35-L35 -> 0 | O35: 10 | P35: =O35*G35 -> 1100 | Q35: 6.75 | R35: 9606 | T35: =R35*G35 -> 1056660 | U35: 25kg/bag，散装 | V35: CIF | W35: MUNDRA | X35: =2950*4 -> 11800 | Y35: =43*4 -> 172 | Z35: =4800*4 -> 19200
A36: 毛晓翔 | B36: LC90 | C36: Polynomous Industries Private Limited | D36: ZJCHDW-20260706-030 | E36: 46240 | F36: CH883 | G36: 55 | H36: 1400 | I36: =G36*H36 -> 77000 | J36: 55 | K36: =G36-J36 -> 0 | L36: 0 | M36: =I36-L36 -> 77000 | N36: =J36*H36-L36 -> 77000 | O36: 200 | P36: =O36*G36 -> 11000 | Q36: 6.75 | R36: 8601 | T36: =R36*G36 -> 473055 | U36: 25kg/bag，散装 | V36: CIF | W36: NHAVA SHEVA | X36: =1950*2 -> 3900 | Y36: =43*2 -> 86 | Z36: =4800*2 -> 9600
A37: 毛晓翔 | B37: LC90 | C37: Polynomous Industries Private Limited | D37: ZJCHDW-20260706-030 | E37: 46240 | F37: CH811 | G37: 27.5 | H37: 1400 | I37: =G37*H37 -> 38500 | J37: 27.5 | K37: =G37-J37 -> 0 | L37: 0 | M37: =I37-L37 -> 38500 | N37: =J37*H37-L37 -> 38500 | O37: 200 | P37: =O37*G37 -> 5500 | Q37: 6.75 | R37: 8601 | T37: =R37*G37 -> 236527.5 | U37: 25kg/bag，散装 | V37: CIF | W37: NHAVA SHEVA | X37: =1950 -> 1950 | Y37: =43 -> 43 | Z37: 4800
A38: 杨玉赏 | B38: 100TT | C38: DARU COMMERCE CO., LTD. | D38: ZJCHDW-20260710-031 | E38: 46244 | F38: CH883 | G38: 1 | H38: 1340 | I38: =G38*H38 -> 1340 | J38: 1 | K38: =G38-J38 -> 0 | L38: =生物收款!E18 -> 1340 | M38: =I38-L38 -> 0 | N38: =J38*H38-L38 -> 0 | O38: 0 | P38: =O38*G38 -> 0 | Q38: 6.78 | R38: 8729 | S38: 8602 | T38: =R38*G38 -> 8729 | U38: 25kg/bag，带托盘 | V38: CIF | W38: BUSAN | X38: =0 -> 0 | Y38: 10 | Z38: 1400
A39: 杨玉赏 | B39: LC60 | C39: ABBEY VIETNAM JOINT STOCK COMPANY | D39: ZJCHDW-20260710-032 | E39: 46265 | F39: N326 | G39: 93.6 | H39: 1085 | I39: =G39*H39 -> 101556 | J39: 93.6 | K39: =G39-J39 -> 0 | L39: 0 | M39: =I39-L39 -> 101556 | N39: =J39*H39-L39 -> 101556 | O39: 0 | P39: =O39*G39 -> 0 | Q39: 6.78 | R39: 6957 | S39: 6600 | T39: =R39*G39 -> 651175.2 | U39: 20公斤带托盘 | V39: CIF | W39: Hai Phong | X39: =4*600 -> 2400 | Y39: =4*40 -> 160 | Z39: =4*5000 -> 20000
